Workbook
Name CM: #REF!
Name CMAC: [1]CM!#REF!
Name CMAC: [2]CM!#REF!
Name CR: #REF!
Name CRAC: [1]CR!#REF!
Name CRAC: [2]CR!#REF!
Name CREDEP: #REF!
Name d: #REF!
Name DATA11: '[3]BASE DATA'!$A$1:$B$111
Name DATA11: '[4]BASE DATA'!$A$1:$B$111
Name DATA12: '[3]BASE DATA'!$A$2:$B$112
Name DATA12: '[4]BASE DATA'!$A$2:$B$112
Name DATA13: '[3]BASE DATA'!$A$2:$B$113
Name DATA13: '[4]BASE DATA'!$A$2:$B$113
Name DATA14: '[3]BASE DATA'!$A$1:$B$114
Name DATA14: '[4]BASE DATA'!$A$1:$B$114
Name DATA4: '[3]BASE DATA'!$A$2:$B$85
Name DATA4: '[4]BASE DATA'!$A$2:$B$85
Name DATA5: '[3]BASE DATA'!$A$1:$B$87
Name DATA5: '[4]BASE DATA'!$A$1:$B$87
Name DATA6: '[3]BASE DATA'!$A$1:$B$88
Name DATA6: '[4]BASE DATA'!$A$1:$B$88
Name DATA7: '[3]BASE DATA'!$A$2:$B$89
Name DATA7: '[4]BASE DATA'!$A$2:$B$89
Name DATA8: '[3]BASE DATA'!$A$1:$B$90
Name DATA8: '[4]BASE DATA'!$A$1:$B$90
Name DATA9: '[3]BASE DATA'!$A$1:$B$91
Name DATA9: '[4]BASE DATA'!$A$1:$B$91
Name DEPDEP: #REF!
Name EDP: [1]ED!#REF!
Name EDP: [2]ED!#REF!
Name EDPYME: #REF!
Name EstatalAgregado: #REF!
Name EstatalPorTipo: #REF!
Name FECHA: '[5]GRUPOS POR TIPO'!$D$3:$IV$3
Name FECHA: '[6]GRUPOS POR TIPO'!$D$3:$IV$3
Name GAdmin: #REF!
Name GAdmin: #REF!
Name Indic.Propuestos: #REF!
Name INDICE: #REF!
Name IngresF: #REF!
Name IngresF: #REF!
Name MFinanc: #REF!
Name MFinanc: #REF!
Name PrivadoAgregado: #REF!
Name PrivadoPorTipos: #REF!
Name SIFAgregado: #REF!
Name SIFporTipo: '[7]SIST FIN TOTAL POR TIPO'!$3:$8
Name Utilid: #REF!
Name Utilid: #REF!

Sheet Definic tipos cred SBS
A2: CLASIFICACIÓN DE CRÉDITOS
A4: La Resolución SBS N° 2368-2023, que modifica el "Reglamento para la Evaluación y Clasificación del Deudor y la Exigencia de Provisiones" (Resolución SBS N° 11356-2008), establece nuevos criterios para la tipificación de créditos los cuales entraron en vigor en octubre de 2024, estableciéndose las siguientes definiciones:
A6: Corporativos
A7: Créditos corporativos del sector real: Créditos otorgados a personas o entes jurídicos con ventas o ingresos anuales mayores a S/ 200 millones en los dos últimos periodos, declarados a la Autoridad Tributaria o de acuerdo a los estados financieros anuales auditados más recientes. Adicionalmente, se consideran como créditos corporativos a los créditos soberanos, créditos concedidos a bancos multilaterales de desarrollo, a entidades del sector público, a intermediarios de valores, a empresas del sistema financiero, a empresas del sistema de seguros, a los patrimonios autónomos de seguro de crédito, a fondos de garantía constituidos conforme a Ley y a otros fondos de garantía
A9: Créditos a Grandes empresas
A10: Créditos otorgados a personas o entes jurídicos con ventas o ingresos anuales mayores a S/ 20 millones en los dos últimos períodos, declarados a la Autoridad Tributaria.
A12: Créditos a Medianas empresas
A13: Créditos otorgados a personas o entes jurídicos que no cumplen con las condiciones para ser tipificados como corporativos o grandes empresas y que hayan registrado ventas o ingresos anuales de actividades ordinarias en el último período declarado a la Autoridad Tributaria mayores a S/ 5 millones y no cumplen con las características para ser clasificados como corporativos o grandes empresas.
A15: Créditos a Pequeñas empresas
A16: Créditos destinados a financiar actividades de producción, comercialización, prestación de servicios u otras actividades empresariales, otorgados a personas jurídicas o personas naturales que hayan registrado un nivel de ventas o ingresos anuales de actividades ordinarias en el último período no mayor a S/ 5 millones y siempre que su nivel de endeudamiento total en el sistema financiero sea mayor a S/ 20 mil en al menos uno de los últimos 6 meses, o siempre que el nuevo crédito desembolsado sea mayor a dicho monto. En el caso de persona natural, el nivel de endeudamiento total en el sistema financiero antes mencionado no incluye los créditos hipotecarios para vivienda.
A18: Créditos a Microempresas
A19: Créditos destinados a financiar actividades de producción, comercialización, prestación de servicios u otras actividades empresariales, otorgados a personas jurídicas o personas naturales que hayan registrado un nivel de ventas o ingresos anuales en el último período no mayor a S/ 5 millones, y siempre que su nivel de endeudamiento total en el sistema financiero sea no mayor a S/ 20 mil en los últimos 6 meses, y que el nuevo crédito desembolsado sea no mayor a S/ 20 mil. En el caso de persona natural, el nivel de endeudamiento total en el sistema financiero antes mencionado no incluye los créditos hipotecarios para vivienda.
... A25: Créditos otorgados a personas naturales para la adquisición, construcción, refacción, remodelación, ampliación, mejoramiento y subdivisión de vivienda propia, siempre que tales créditos se otorguen amparados con hipotecas debidamente inscritas; sea que estos créditos se otorguen por el sistema convencional de préstamo hipotecario, de letras hipotecarias o por cualquier otro sistema de similares características.

Sheet BaseIBK
A1: Departamento | B1: Provincia | C1: Distrito | D1: Ubigeo | E1: Poblacion | F1: Nro_mypes | G1: ventas_mypes_totales | H1: ventas_mypes_promedio | I1: Corp_Banca_Multiple | J1: Corp_Empresas_Financieras | K1: Corp_Cajas_Municipales | L1: Corp_Cajas_Rurales_Ah_y_Cred | M1: Corp_Empresas_Creditos | N1: Corp_Total | O1: GE_Banca_Multiple | P1: GE_Empresas_Financieras | Q1: GE_Cajas_Municipales | R1: GE_Cajas_Rurales_Ah_y_Cred | S1: GE_Empresas_Creditos | T1: GE_Total | U1: ME_Banca_Multiple | V1: ME_Empresas_Financieras | W1: ME_Cajas_Municipales | X1: ME_Cajas_Rurales_Ah_y_Cred | Y1: ME_Empresas_Creditos | Z1: ME_Total | AA1: PE_Banca_Multiple | AB1: PE_Empresas_Financieras | AC1: PE_Cajas_Municipales | AD1: PE_Cajas_Rurales_Ah_y_Cred | AE1: PE_Empresas_Creditos | AF1: PE_Total | AG1: MI_Banca_Multiple | AH1: MI_Empresas_Financieras | AI1: MI_Cajas_Municipales | AJ1: MI_Cajas_Rurales_Ah_y_Cred | AK1: MI_Empresas_Creditos | AL1: MI_Total | AM1: Con_Banca_Multiple | AN1: Con_Empresas_Financieras | AO1: Con_Cajas_Municipales | AP1: Con_Cajas_Rurales_Ah_y_Cred | AQ1: Con_Empresas_Creditos | AR1: Con_Total | AS1: Hi_Banca_Multiple | AT1: Hi_Empresas_Financieras | AU1: Hi_Cajas_Municipales | AV1: Hi_Cajas_Rurales_Ah_y_Cred | AW1: Hi_Empresas_Creditos | AX1: Hi_Total | AY1: CD_Total | AZ1: Mas100milhab | BA1: n_rt | BB1: venta_mean_rt | BC1: venta_sum_rt | BD1: plin_mean_rt | BE1: izipay_mean_rt | BF1: n_univ | BG1: plin_mean_univ | BH1: izipay_mean_univ
A2: AMAZONAS | B2: CHACHAPOYAS | C2: CHACHAPOYAS | D2: 010101 | E2: 41335 | F2: 299 | G2: 268.7399 | H2: 0.8987958 | I2: 0.01 | J2: 0 | K2: 0 | L2: 0 | M2: 0 | N2: 0.01 | O2: 0 | P2: 0 | Q2: 111.3 | R2: 0 | S2: 0 | T2: 111.3 | U2: 568.84 | V2: 0 | W2: 3756.42 | X2: 0 | Y2: 0 | Z2: 4325.26 | AA2: 100470.98 | AB2: 36731.51 | AC2: 114461.2 | AD2: 5389.1 | AE2: 0 | AF2: 257052.79 | AG2: 9009.28 | AH2: 9546 | AI2: 15790.21 | AJ2: 1719.29 | AK2: 0 | AL2: 36064.78 | AM2: 6828.51 | AN2: 10346.22 | AO2: 51571.89 | AP2: 714.37 | AQ2: 0 | AR2: 69460.99 | AS2: 5608.56 | AT2: 0 | AU2: 6468.75 | AV2: 0 | AW2: 0 | AX2: 12077.31 | AY2: 379092.44 | AZ2: 0 | BA2: 22 | BB2: 34183.793 | BC2: 752043.45 | BD2: 34.090909 | BE2: 1546.709 | BF2: 737 | BG2: 1286.6637 | BH2: 1968.134
A3: AMAZONAS | B3: CHACHAPOYAS | C3: ASUNCION | D3: 010102 | E3: 271 | F3: . | G3: . | H3: . | I3: 0 | J3: 0 | K3: 0 | L3: 0 | M3: 0 | N3: 0 | O3: 0 | P3: 0 | Q3: 0 | R3: 0 | S3: 0 | T3: 0 | U3: 0 | V3: 0 | W3: 0 | X3: 0 | Y3: 0 | Z3: 0 | AA3: 0 | AB3: 0 | AC3: 0 | AD3: 0 | AE3: 0 | AF3: 0 | AG3: 0 | AH3: 0 | AI3: 0 | AJ3: 0 | AK3: 0 | AL3: 0 | AM3: 0 | AN3: 0 | AO3: 0 | AP3: 0 | AQ3: 0 | AR3: 0 | AS3: 0 | AT3: 0 | AU3: 0 | AV3: 0 | AW3: 0 | AX3: 0 | AY3: 0 | AZ3: 0 | BA3: 0 | BB3: 0 | BC3: 0 | BD3: 0 | BE3: 0 | BF3: 1 | BG3: 0 | BH3: 0
A4: AMAZONAS | B4: CHACHAPOYAS | C4: BALSAS | D4: 010103 | E4: 1137 | F4: . | G4: . | H4: . | I4: 0 | J4: 0 | K4: 0 | L4: 0 | M4: 0 | N4: 0 | O4: 0 | P4: 0 | Q4: 0 | R4: 0 | S4: 0 | T4: 0 | U4: 0 | V4: 0 | W4: 0 | X4: 0 | Y4: 0 | Z4: 0 | AA4: 0 | AB4: 0 | AC4: 0 | AD4: 0 | AE4: 0 | AF4: 0 | AG4: 0 | AH4: 0 | AI4: 0 | AJ4: 0 | AK4: 0 | AL4: 0 | AM4: 0 | AN4: 0 | AO4: 0 | AP4: 0 | AQ4: 0 | AR4: 0 | AS4: 0 | AT4: 0 | AU4: 0 | AV4: 0 | AW4: 0 | AX4: 0 | AY4: 0 | AZ4: 0 | BA4: 0 | BB4: 0 | BC4: 0 | BD4: 0 | BE4: 0 | BF4: 7 | BG4: 0 | BH4: 0
A5: AMAZONAS | B5: CHACHAPOYAS | C5: CHETO | D5: 010104 | E5: 713 | F5: 1 | G5: 0.205 | H5: 0.205 | I5: 0 | J5: 0 | K5: 0 | L5: 0 | M5: 0 | N5: 0 | O5: 0 | P5: 0 | Q5: 0 | R5: 0 | S5: 0 | T5: 0 | U5: 0 | V5: 0 | W5: 0 | X5: 0 | Y5: 0 | Z5: 0 | AA5: 0 | AB5: 0 | AC5: 0 | AD5: 0 | AE5: 0 | AF5: 0 | AG5: 0 | AH5: 0 | AI5: 0 | AJ5: 0 | AK5: 0 | AL5: 0 | AM5: 0 | AN5: 0 | AO5: 0 | AP5: 0 | AQ5: 0 | AR5: 0 | AS5: 0 | AT5: 0 | AU5: 0 | AV5: 0 | AW5: 0 | AX5: 0 | AY5: 0 | AZ5: 0 | BA5: 0 | BB5: 0 | BC5: 0 | BD5: 0 | BE5: 0 | BF5: 5 | BG5: 0 | BH5: 0
A6: AMAZONAS | B6: CHACHAPOYAS | C6: CHILIQUIN | D6: 010105 | E6: 561 | F6: . | G6: . | H6: . | I6: 0 | J6: 0 | K6: 0 | L6: 0 | M6: 0 | N6: 0 | O6: 0 | P6: 0 | Q6: 0 | R6: 0 | S6: 0 | T6: 0 | U6: 0 | V6: 0 | W6: 0 | X6: 0 | Y6: 0 | Z6: 0 | AA6: 0 | AB6: 0 | AC6: 0 | AD6: 0 | AE6: 0 | AF6: 0 | AG6: 0 | AH6: 0 | AI6: 0 | AJ6: 0 | AK6: 0 | AL6: 0 | AM6: 0 | AN6: 0 | AO6: 0 | AP6: 0 | AQ6: 0 | AR6: 0 | AS6: 0 | AT6: 0 | AU6: 0 | AV6: 0 | AW6: 0 | AX6: 0 | AY6: 0 | AZ6: 0 | BA6: 0 | BB6: 0 | BC6: 0 | BD6: 0 | BE6: 0 | BF6: 2 | BG6: 0 | BH6: 0
A7: AMAZONAS | B7: CHACHAPOYAS | C7: CHUQUIBAMBA | D7: 010106 | E7: 1884 | F7: . | G7: . | H7: . | I7: 0 | J7: 0 | K7: 0 | L7: 0 | M7: 0 | N7: 0 | O7: 0 | P7: 0 | Q7: 0 | R7: 0 | S7: 0 | T7: 0 | U7: 0 | V7: 0 | W7: 0 | X7: 0 | Y7: 0 | Z7: 0 | AA7: 0 | AB7: 0 | AC7: 0 | AD7: 0 | AE7: 0 | AF7: 0 | AG7: 0 | AH7: 0 | AI7: 0 | AJ7: 0 | AK7: 0 | AL7: 0 | AM7: 0 | AN7: 0 | AO7: 0 | AP7: 0 | AQ7: 0 | AR7: 0 | AS7: 0 | AT7: 0 | AU7: 0 | AV7: 0 | AW7: 0 | AX7: 0 | AY7: 0 | AZ7: 0 | BA7: 0 | BB7: 0 | BC7: 0 | BD7: 0 | BE7: 0 | BF7: 1 | BG7: 0 | BH7: 0
A8: AMAZONAS | B8: CHACHAPOYAS | C8: GRANADA | D8: 010107 | E8: 549 | F8: . | G8: . | H8: . | I8: 0 | J8: 0 | K8: 0 | L8: 0 | M8: 0 | N8: 0 | O8: 0 | P8: 0 | Q8: 0 | R8: 0 | S8: 0 | T8: 0 | U8: 0 | V8: 0 | W8: 0 | X8: 0 | Y8: 0 | Z8: 0 | AA8: 0 | AB8: 0 | AC8: 0 | AD8: 0 | AE8: 0 | AF8: 0 | AG8: 0 | AH8: 0 | AI8: 0 | AJ8: 0 | AK8: 0 | AL8: 0 | AM8: 0 | AN8: 0 | AO8: 0 | AP8: 0 | AQ8: 0 | AR8: 0 | AS8: 0 | AT8: 0 | AU8: 0 | AV8: 0 | AW8: 0 | AX8: 0 | AY8: 0 | AZ8: 0 | BA8: 0 | BB8: 0 | BC8: 0 | BD8: 0 | BE8: 0 | BF8: 1 | BG8: 0 | BH8: 0
A9: AMAZONAS | B9: CHACHAPOYAS | C9: HUANCAS | D9: 010108 | E9: 1526 | F9: . | G9: . | H9: . | I9: 0 | J9: 0 | K9: 0 | L9: 0 | M9: 0 | N9: 0 | O9: 0 | P9: 0 | Q9: 0 | R9: 0 | S9: 0 | T9: 0 | U9: 0 | V9: 0 | W9: 0 | X9: 0 | Y9: 0 | Z9: 0 | AA9: 0 | AB9: 0 | AC9: 0 | AD9: 0 | AE9: 0 | AF9: 0 | AG9: 0 | AH9: 0 | AI9: 0 | AJ9: 0 | AK9: 0 | AL9: 0 | AM9: 0 | AN9: 0 | AO9: 0 | AP9: 0 | AQ9: 0 | AR9: 0 | AS9: 0 | AT9: 0 | AU9: 0 | AV9: 0 | AW9: 0 | AX9: 0 | AY9: 0 | AZ9: 0 | BA9: 0 | BB9: 0 | BC9: 0 | BD9: 0 | BE9: 0 | BF9: 3 | BG9: 0 | BH9: 0
A10: AMAZONAS | B10: CHACHAPOYAS | C10: LA JALCA | D10: 010109 | E10: 3418 | F10: 3 | G10: 0.904 | H10: 0.3013333 | I10: 0 | J10: 0 | K10: 0 | L10: 0 | M10: 0 | N10: 0 | O10: 0 | P10: 0 | Q10: 0 | R10: 0 | S10: 0 | T10: 0 | U10: 0 | V10: 0 | W10: 0 | X10: 0 | Y10: 0 | Z10: 0 | AA10: 0 | AB10: 0 | AC10: 0 | AD10: 0 | AE10: 0 | AF10: 0 | AG10: 0 | AH10: 0 | AI10: 0 | AJ10: 0 | AK10: 0 | AL10: 0 | AM10: 0 | AN10: 0 | AO10: 0 | AP10: 0 | AQ10: 0 | AR10: 0 | AS10: 0 | AT10: 0 | AU10: 0 | AV10: 0 | AW10: 0 | AX10: 0 | AY10: 0 | AZ10: 0 | BA10: 1 | BB10: 191781.83 | BC10: 191781.83 | BD10: 0 | BE10: 0 | BF10: 33 | BG10: 693.78485 | BH10: 0
A11: AMAZONAS | B11: CHACHAPOYAS | C11: LEIMEBAMBA | D11: 010110 | E11: 3738 | F11: 3 | G11: 1.596 | H11: 0.532 | I11: 0 | J11: 0 | K11: 0 | L11: 0 | M11: 0 | N11: 0 | O11: 0 | P11: 0 | Q11: 0 | R11: 0 | S11: 0 | T11: 0 | U11: 0 | V11: 0 | W11: 0 | X11: 0 | Y11: 0 | Z11: 0 | AA11: 0 | AB11: 0 | AC11: 0 | AD11: 0 | AE11: 0 | AF11: 0 | AG11: 0 | AH11: 0 | AI11: 0 | AJ11: 0 | AK11: 0 | AL11: 0 | AM11: 0 | AN11: 0 | AO11: 0 | AP11: 0 | AQ11: 0 | AR11: 0 | AS11: 0 | AT11: 0 | AU11: 0 | AV11: 0 | AW11: 0 | AX11: 0 | AY11: 0 | AZ11: 0 | BA11: 0 | BB11: 0 | BC11: 0 | BD11: 0 | BE11: 0 | BF11: 14 | BG11: 0 | BH11: 0
A12: AMAZONAS | B12: CHACHAPOYAS | C12: LEVANTO | D12: 010111 | E12: 774 | F12: . | G12: . | H12: . | I12: 0 | J12: 0 | K12: 0 | L12: 0 | M12: 0 | N12: 0 | O12: 0 | P12: 0 | Q12: 0 | R12: 0 | S12: 0 | T12: 0 | U12: 0 | V12: 0 | W12: 0 | X12: 0 | Y12: 0 | Z12: 0 | AA12: 0 | AB12: 0 | AC12: 0 | AD12: 0 | AE12: 0 | AF12: 0 | AG12: 0 | AH12: 0 | AI12: 0 | AJ12: 0 | AK12: 0 | AL12: 0 | AM12: 0 | AN12: 0 | AO12: 0 | AP12: 0 | AQ12: 0 | AR12: 0 | AS12: 0 | AT12: 0 | AU12: 0 | AV12: 0 | AW12: 0 | AX12: 0 | AY12: 0 | AZ12: 0 | BA12: 0 | BB12: 0 | BC12: 0 | BD12: 0 | BE12: 0 | BF12: 2 | BG12: 0 | BH12: 0
A13: AMAZONAS | B13: CHACHAPOYAS | C13: MAGDALENA | D13: 010112 | E13: 900 | F13: . | G13: . | H13: . | I13: 0 | J13: 0 | K13: 0 | L13: 0 | M13: 0 | N13: 0 | O13: 0 | P13: 0 | Q13: 0 | R13: 0 | S13: 0 | T13: 0 | U13: 0 | V13: 0 | W13: 0 | X13: 0 | Y13: 0 | Z13: 0 | AA13: 0 | AB13: 0 | AC13: 0 | AD13: 0 | AE13: 0 | AF13: 0 | AG13: 0 | AH13: 0 | AI13: 0 | AJ13: 0 | AK13: 0 | AL13: 0 | AM13: 0 | AN13: 0 | AO13: 0 | AP13: 0 | AQ13: 0 | AR13: 0 | AS13: 0 | AT13: 0 | AU13: 0 | AV13: 0 | AW13: 0 | AX13: 0 | AY13: 0 | AZ13: 0 | BA13: 0 | BB13: 0 | BC13: 0 | BD13: 0 | BE13: 0 | BF13: 4 | BG13: 0 | BH13: 0
A14: AMAZONAS | B14: CHACHAPOYAS | C14: MARISCAL CASTILLA | D14: 010113 | E14: 1631 | F14: 4 | G14: 2.956087 | H14: 0.7390218 | I14: 0 | J14: 0 | K14: 0 | L14: 0 | M14: 0 | N14: 0 | O14: 0 | P14: 0 | Q14: 0 | R14: 0 | S14: 0 | T14: 0 | U14: 0 | V14: 0 | W14: 0 | X14: 0 | Y14: 0 | Z14: 0 | AA14: 0 | AB14: 0 | AC14: 0 | AD14: 0 | AE14: 0 | AF14: 0 | AG14: 0 | AH14: 0 | AI14: 0 | AJ14: 0 | AK14: 0 | AL14: 0 | AM14: 0 | AN14: 0 | AO14: 0 | AP14: 0 | AQ14: 0 | AR14: 0 | AS14: 0 | AT14: 0 | AU14: 0 | AV14: 0 | AW14: 0 | AX14: 0 | AY14: 0 | AZ14: 0 | BA14: 0 | BB14: 0 | BC14: 0 | BD14: 0 | BE14: 0 | BF14: 1 | BG14: 0 | BH14: 0
A15: AMAZONAS | B15: CHACHAPOYAS | C15: MOLINOPAMPA | D15: 010114 | E15: 2201 | F15: 3 | G15: 0.70128 | H15: 0.23376 | I15: 0 | J15: 0 | K15: 0 | L15: 0 | M15: 0 | N15: 0 | O15: 0 | P15: 0 | Q15: 0 | R15: 0 | S15: 0 | T15: 0 | U15: 0 | V15: 0 | W15: 0 | X15: 0 | Y15: 0 | Z15: 0 | AA15: 0 | AB15: 0 | AC15: 0 | AD15: 0 | AE15: 0 | AF15: 0 | AG15: 0 | AH15: 0 | AI15: 0 | AJ15: 0 | AK15: 0 | AL15: 0 | AM15: 0 | AN15: 0 | AO15: 0 | AP15: 0 | AQ15: 0 | AR15: 0 | AS15: 0 | AT15: 0 | AU15: 0 | AV15: 0 | AW15: 0 | AX15: 0 | AY15: 0 | AZ15: 0 | BA15: 0 | BB15: 0 | BC15: 0 | BD15: 0 | BE15: 0 | BF15: 10 | BG15: 0 | BH15: 0
A16: AMAZONAS | B16: CHACHAPOYAS | C16: MONTEVIDEO | D16: 010115 | E16: 459 | F16: . | G16: . | H16: . | I16: 0 | J16: 0 | K16: 0 | L16: 0 | M16: 0 | N16: 0 | O16: 0 | P16: 0 | Q16: 0 | R16: 0 | S16: 0 | T16: 0 | U16: 0 | V16: 0 | W16: 0 | X16: 0 | Y16: 0 | Z16: 0 | AA16: 0 | AB16: 0 | AC16: 0 | AD16: 0 | AE16: 0 | AF16: 0 | AG16: 0 | AH16: 0 | AI16: 0 | AJ16: 0 | AK16: 0 | AL16: 0 | AM16: 0 | AN16: 0 | AO16: 0 | AP16: 0 | AQ16: 0 | AR16: 0 | AS16: 0 | AT16: 0 | AU16: 0 | AV16: 0 | AW16: 0 | AX16: 0 | AY16: 0 | AZ16: 0 | BA16: 0 | BB16: 0 | BC16: 0 | BD16: 0 | BE16: 0 | BF16: 1 | BG16: 0 | BH16: 0
A17: AMAZONAS | B17: CHACHAPOYAS | C17: OLLEROS | D17: 010116 | E17: 446 | F17: 1 | G17: 0.324 | H17: 0.324 | I17: 0 | J17: 0 | K17: 0 | L17: 0 | M17: 0 | N17: 0 | O17: 0 | P17: 0 | Q17: 0 | R17: 0 | S17: 0 | T17: 0 | U17: 0 | V17: 0 | W17: 0 | X17: 0 | Y17: 0 | Z17: 0 | AA17: 0 | AB17: 0 | AC17: 0 | AD17: 0 | AE17: 0 | AF17: 0 | AG17: 0 | AH17: 0 | AI17: 0 | AJ17: 0 | AK17: 0 | AL17: 0 | AM17: 0 | AN17: 0 | AO17: 0 | AP17: 0 | AQ17: 0 | AR17: 0 | AS17: 0 | AT17: 0 | AU17: 0 | AV17: 0 | AW17: 0 | AX17: 0 | AY17: 0 | AZ17: 0 | BA17: 0 | BB17: 0 | BC17: 0 | BD17: 0 | BE17: 0 | BF17: 1 | BG17: 0 | BH17: 0
A18: AMAZONAS | B18: CHACHAPOYAS | C18: QUINJALCA | D18: 010117 | E18: 763 | F18: . | G18: . | H18: . | I18: 0 | J18: 0 | K18: 0 | L18: 0 | M18: 0 | N18: 0 | O18: 0 | P18: 0 | Q18: 0 | R18: 0 | S18: 0 | T18: 0 | U18: 0 | V18: 0 | W18: 0 | X18: 0 | Y18: 0 | Z18: 0 | AA18: 0 | AB18: 0 | AC18: 0 | AD18: 0 | AE18: 0 | AF18: 0 | AG18: 0 | AH18: 0 | AI18: 0 | AJ18: 0 | AK18: 0 | AL18: 0 | AM18: 0 | AN18: 0 | AO18: 0 | AP18: 0 | AQ18: 0 | AR18: 0 | AS18: 0 | AT18: 0 | AU18: 0 | AV18: 0 | AW18: 0 | AX18: 0 | AY18: 0 | AZ18: 0 | BA18: 0 | BB18: 0 | BC18: 0 | BD18: 0 | BE18: 0 | BF18: 1 | BG18: 0 | BH18: 0
A19: AMAZONAS | B19: CHACHAPOYAS | C19: SAN FRANCISCO DE DAGUAS | D19: 010118 | E19: 332 | F19: . | G19: . | H19: . | I19: 0 | J19: 0 | K19: 0 | L19: 0 | M19: 0 | N19: 0 | O19: 0 | P19: 0 | Q19: 0 | R19: 0 | S19: 0 | T19: 0 | U19: 0 | V19: 0 | W19: 0 | X19: 0 | Y19: 0 | Z19: 0 | AA19: 0 | AB19: 0 | AC19: 0 | AD19: 0 | AE19: 0 | AF19: 0 | AG19: 0 | AH19: 0 | AI19: 0 | AJ19: 0 | AK19: 0 | AL19: 0 | AM19: 0 | AN19: 0 | AO19: 0 | AP19: 0 | AQ19: 0 | AR19: 0 | AS19: 0 | AT19: 0 | AU19: 0 | AV19: 0 | AW19: 0 | AX19: 0 | AY19: 0 | AZ19: 0 | BA19: 0 | BB19: 0 | BC19: 0 | BD19: 0 | BE19: 0 | BF19: 1 | BG19: 0 | BH19: 0
A20: AMAZONAS | B20: CHACHAPOYAS | C20: SAN ISIDRO DE MAINO | D20: 010119 | E20: 570 | F20: . | G20: . | H20: . | I20: 0 | J20: 0 | K20: 0 | L20: 0 | M20: 0 | N20: 0 | O20: 0 | P20: 0 | Q20: 0 | R20: 0 | S20: 0 | T20: 0 | U20: 0 | V20: 0 | W20: 0 | X20: 0 | Y20: 0 | Z20: 0 | AA20: 0 | AB20: 0 | AC20: 0 | AD20: 0 | AE20: 0 | AF20: 0 | AG20: 0 | AH20: 0 | AI20: 0 | AJ20: 0 | AK20: 0 | AL20: 0 | AM20: 0 | AN20: 0 | AO20: 0 | AP20: 0 | AQ20: 0 | AR20: 0 | AS20: 0 | AT20: 0 | AU20: 0 | AV20: 0 | AW20: 0 | AX20: 0 | AY20: 0 | AZ20: 0 | BA20: 0 | BB20: 0 | BC20: 0 | BD20: 0 | BE20: 0 | BF20: 2 | BG20: 0 | BH20: 0
A21: AMAZONAS | B21: CHACHAPOYAS | C21: SOLOCO | D21: 010120 | E21: 1224 | F21: . | G21: . | H21: . | I21: 0 | J21: 0 | K21: 0 | L21: 0 | M21: 0 | N21: 0 | O21: 0 | P21: 0 | Q21: 0 | R21: 0 | S21: 0 | T21: 0 | U21: 0 | V21: 0 | W21: 0 | X21: 0 | Y21: 0 | Z21: 0 | AA21: 0 | AB21: 0 | AC21: 0 | AD21: 0 | AE21: 0 | AF21: 0 | AG21: 0 | AH21: 0 | AI21: 0 | AJ21: 0 | AK21: 0 | AL21: 0 | AM21: 0 | AN21: 0 | AO21: 0 | AP21: 0 | AQ21: 0 | AR21: 0 | AS21: 0 | AT21: 0 | AU21: 0 | AV21: 0 | AW21: 0 | AX21: 0 | AY21: 0 | AZ21: 0 | BA21: 0 | BB21: 0 | BC21: 0 | BD21: 0 | BE21: 0 | BF21: 1 | BG21: 0 | BH21: 0
A22: AMAZONAS | B22: CHACHAPOYAS | C22: SONCHE | D22: 010121 | E22: 286 | F22: . | G22: . | H22: . | I22: 0 | J22: 0 | K22: 0 | L22: 0 | M22: 0 | N22: 0 | O22: 0 | P22: 0 | Q22: 0 | R22: 0 | S22: 0 | T22: 0 | U22: 0 | V22: 0 | W22: 0 | X22: 0 | Y22: 0 | Z22: 0 | AA22: 0 | AB22: 0 | AC22: 0 | AD22: 0 | AE22: 0 | AF22: 0 | AG22: 0 | AH22: 0 | AI22: 0 | AJ22: 0 | AK22: 0 | AL22: 0 | AM22: 0 | AN22: 0 | AO22: 0 | AP22: 0 | AQ22: 0 | AR22: 0 | AS22: 0 | AT22: 0 | AU22: 0 | AV22: 0 | AW22: 0 | AX22: 0 | AY22: 0 | AZ22: 0 | BA22: . | BB22: . | BC22: . | BD22: . | BE22: . | BF22: . | BG22: . | BH22: .
A23: AMAZONAS | B23: BAGUA | C23: BAGUA | D23: 010201 | E23: 30790 | F23: 133 | G23: 125.9749 | H23: 0.94718 | I23: 0 | J23: 0 | K23: 0 | L23: 0 | M23: 0 | N23: 0 | O23: 0 | P23: 0 | Q23: 272.39 | R23: 0 | S23: 0 | T23: 272.39 | U23: 0 | V23: 0 | W23: 1362.79 | X23: 0 | Y23: 0 | Z23: 1362.79 | AA23: 38337.75 | AB23: 0 | AC23: 42795.73 | AD23: 0 | AE23: 1505.09 | AF23: 82638.57 | AG23: 6765.89 | AH23: 0 | AI23: 4024.05 | AJ23: 0 | AK23: 1538.99 | AL23: 12328.93 | AM23: 2883.06 | AN23: 0 | AO23: 12404.9 | AP23: 0 | AQ23: 417.21 | AR23: 15705.17 | AS23: 1998.77 | AT23: 0 | AU23: 6584.03 | AV23: 0 | AW23: 0 | AX23: 8582.8 | AY23: 120890.65 | AZ23: 0 | BA23: 10 | BB23: 49268.931 | BC23: 492689.3 | BD23: 0 | BE23: 2.99 | BF23: 308 | BG23: 1718.149 | BH23: 169.035
A24: AMAZONAS | B24: BAGUA | C24: ARAMANGO | D24: 010202 | E24: 9613 | F24: . | G24: . | H24: . | I24: 0 | J24: 0 | K24: 0 | L24: 0 | M24: 0 | N24: 0 | O24: 0 | P24: 0 | Q24: 0 | R24: 0 | S24: 0 | T24: 0 | U24: 0 | V24: 0 | W24: 0 | X24: 0 | Y24: 0 | Z24: 0 | AA24: 0 | AB24: 0 | AC24: 0 | AD24: 0 | AE24: 0 | AF24: 0 | AG24: 0 | AH24: 0 | AI24: 0 | AJ24: 0 | AK24: 0 | AL24: 0 | AM24: 0 | AN24: 0 | AO24: 0 | AP24: 0 | AQ24: 0 | AR24: 0 | AS24: 0 | AT24: 0 | AU24: 0 | AV24: 0 | AW24: 0 | AX24: 0 | AY24: 0 | AZ24: 0 | BA24: 0 | BB24: 0 | BC24: 0 | BD24: 0 | BE24: 0 | BF24: 28 | BG24: 0 | BH24: 0
A25: AMAZONAS | B25: BAGUA | C25: COPALLIN | D25: 010203 | E25: 4213 | F25: 2 | G25: 0.68 | H25: 0.34 | I25: 0 | J25: 0 | K25: 0 | L25: 0 | M25: 0 | N25: 0 | O25: 0 | P25: 0 | Q25: 0 | R25: 0 | S25: 0 | T25: 0 | U25: 0 | V25: 0 | W25: 0 | X25: 0 | Y25: 0 | Z25: 0 | AA25: 0 | AB25: 0 | AC25: 0 | AD25: 0 | AE25: 0 | AF25: 0 | AG25: 0 | AH25: 0 | AI25: 0 | AJ25: 0 | AK25: 0 | AL25: 0 | AM25: 0 | AN25: 0 | AO25: 0 | AP25: 0 | AQ25: 0 | AR25: 0 | AS25: 0 | AT25: 0 | AU25: 0 | AV25: 0 | AW25: 0 | AX25: 0 | AY25: 0 | AZ25: 0 | BA25: 0 | BB25: 0 | BC25: 0 | BD25: 0 | BE25: 0 | BF25: 8 | BG25: 378.625 | BH25: 0
A26: AMAZONAS | B26: BAGUA | C26: EL PARCO | D26: 010204 | E26: 1251 | F26: . | G26: . | H26: . | I26: 0 | J26: 0 | K26: 0 | L26: 0 | M26: 0 | N26: 0 | O26: 0 | P26: 0 | Q26: 0 | R26: 0 | S26: 0 | T26: 0 | U26: 0 | V26: 0 | W26: 0 | X26: 0 | Y26: 0 | Z26: 0 | AA26: 0 | AB26: 0 | AC26: 0 | AD26: 0 | AE26: 0 | AF26: 0 | AG26: 0 | AH26: 0 | AI26: 0 | AJ26: 0 | AK26: 0 | AL26: 0 | AM26: 0 | AN26: 0 | AO26: 0 | AP26: 0 | AQ26: 0 | AR26: 0 | AS26: 0 | AT26: 0 | AU26: 0 | AV26: 0 | AW26: 0 | AX26: 0 | AY26: 0 | AZ26: 0 | BA26: 0 | BB26: 0 | BC26: 0 | BD26: 0 | BE26: 0 | BF26: 2 | BG26: 0 | BH26: 0
A27: AMAZONAS | B27: BAGUA | C27: IMAZA | D27: 010205 | E27: 34240 | F27: 18 | G27: 10.41557 | H27: 0.578643 | I27: 0 | J27: 0 | K27: 0 | L27: 0 | M27: 0 | N27: 0 | O27: 0 | P27: 0 | Q27: 0 | R27: 0 | S27: 0 | T27: 0 | U27: 0 | V27: 0 | W27: 0 | X27: 0 | Y27: 0 | Z27: 0 | AA27: 0 | AB27: 0 | AC27: 0 | AD27: 0 | AE27: 0 | AF27: 0 | AG27: 0 | AH27: 0 | AI27: 0 | AJ27: 0 | AK27: 0 | AL27: 0 | AM27: 0 | AN27: 0 | AO27: 0 | AP27: 0 | AQ27: 0 | AR27: 0 | AS27: 0 | AT27: 0 | AU27: 0 | AV27: 0 | AW27: 0 | AX27: 0 | AY27: 0 | AZ27: 0 | BA27: 3 | BB27: 173559.76 | BC27: 520679.28 | BD27: 0 | BE27: 0 | BF27: 75 | BG27: 608.07467 | BH27: 0
A28: AMAZONAS | B28: BAGUA | C28: LA PECA | D28: 010206 | E28: 6226 | F28: 5 | G28: 2.024038 | H28: 0.4048076 | I28: 0 | J28: 0 | K28: 0 | L28: 0 | M28: 0 | N28: 0 | O28: 0 | P28: 0 | Q28: 0 | R28: 0 | S28: 0 | T28: 0 | U28: 0 | V28: 0 | W28: 0 | X28: 0 | Y28: 0 | Z28: 0 | AA28: 0 | AB28: 0 | AC28: 35421.71 | AD28: 0 | AE28: 0 | AF28: 35421.71 | AG28: 0 | AH28: 0 | AI28: 5652.14 | AJ28: 0 | AK28: 0 | AL28: 5652.14 | AM28: 0 | AN28: 0 | AO28: 12334.81 | AP28: 0 | AQ28: 0 | AR28: 12334.81 | AS28: 0 | AT28: 0 | AU28: 1271.95 | AV28: 0 | AW28: 0 | AX28: 1271.95 | AY28: 54680.61 | AZ28: 0 | BA28: 1 | BB28: 8894.167 | BC28: 8894.167 | BD28: 2873 | BE28: 0 | BF28: 44 | BG28: 10.072727 | BH28: 0
A29: AMAZONAS | B29: BONGARA | C29: JUMBILLA | D29: 010301 | E29: 1232 | F29: 2 | G29: 0.5465 | H29: 0.27325 | I29: 0 | J29: 0 | K29: 0 | L29: 0 | M29: 0 | N29: 0 | O29: 0 | P29: 0 | Q29: 0 | R29: 0 | S29: 0 | T29: 0 | U29: 0 | V29: 0 | W29: 0 | X29: 0 | Y29: 0 | Z29: 0 | AA29: 0 | AB29: 0 | AC29: 0 | AD29: 0 | AE29: 0 | AF29: 0 | AG29: 0 | AH29: 0 | AI29: 0 | AJ29: 0 | AK29: 0 | AL29: 0 | AM29: 0 | AN29: 0 | AO29: 0 | AP29: 0 | AQ29: 0 | AR29: 0 | AS29: 0 | AT29: 0 | AU29: 0 | AV29: 0 | AW29: 0 | AX29: 0 | AY29: 0 | AZ29: 0 | BA29: 0 | BB29: 0 | BC29: 0 | BD29: 0 | BE29: 0 | BF29: 8 | BG29: 0 | BH29: 0
A30: AMAZONAS | B30: BONGARA | C30: CHISQUILLA | D30: 010302 | E30: 308 | F30: . | G30: . | H30: . | I30: 0 | J30: 0 | K30: 0 | L30: 0 | M30: 0 | N30: 0 | O30: 0 | P30: 0 | Q30: 0 | R30: 0 | S30: 0 | T30: 0 | U30: 0 | V30: 0 | W30: 0 | X30: 0 | Y30: 0 | Z30: 0 | AA30: 0 | AB30: 0 | AC30: 0 | AD30: 0 | AE30: 0 | AF30: 0 | AG30: 0 | AH30: 0 | AI30: 0 | AJ30: 0 | AK30: 0 | AL30: 0 | AM30: 0 | AN30: 0 | AO30: 0 | AP30: 0 | AQ30: 0 | AR30: 0 | AS30: 0 | AT30: 0 | AU30: 0 | AV30: 0 | AW30: 0 | AX30: 0 | AY30: 0 | AZ30: 0 | BA30: . | BB30: . | BC30: . | BD30: . | BE30: . | BF30: . | BG30: . | BH30: .
A31: AMAZONAS | B31: BONGARA | C31: CHURUJA | D31: 010303 | E31: 292 | F31: . | G31: . | H31: . | I31: 0 | J31: 0 | K31: 0 | L31: 0 | M31: 0 | N31: 0 | O31: 0 | P31: 0 | Q31: 0 | R31: 0 | S31: 0 | T31: 0 | U31: 0 | V31: 0 | W31: 0 | X31: 0 | Y31: 0 | Z31: 0 | AA31: 0 | AB31: 0 | AC31: 0 | AD31: 0 | AE31: 0 | AF31: 0 | AG31: 0 | AH31: 0 | AI31: 0 | AJ31: 0 | AK31: 0 | AL31: 0 | AM31: 0 | AN31: 0 | AO31: 0 | AP31: 0 | AQ31: 0 | AR31: 0 | AS31: 0 | AT31: 0 | AU31: 0 | AV31: 0 | AW31: 0 | AX31: 0 | AY31: 0 | AZ31: 0 | BA31: 0 | BB31: 0 | BC31: 0 | BD31: 0 | BE31: 0 | BF31: 1 | BG31: 0 | BH31: 0
A32: AMAZONAS | B32: BONGARA | C32: COROSHA | D32: 010304 | E32: 849 | F32: . | G32: . | H32: . | I32: 0 | J32: 0 | K32: 0 | L32: 0 | M32: 0 | N32: 0 | O32: 0 | P32: 0 | Q32: 0 | R32: 0 | S32: 0 | T32: 0 | U32: 0 | V32: 0 | W32: 0 | X32: 0 | Y32: 0 | Z32: 0 | AA32: 0 | AB32: 0 | AC32: 0 | AD32: 0 | AE32: 0 | AF32: 0 | AG32: 0 | AH32: 0 | AI32: 0 | AJ32: 0 | AK32: 0 | AL32: 0 | AM32: 0 | AN32: 0 | AO32: 0 | AP32: 0 | AQ32: 0 | AR32: 0 | AS32: 0 | AT32: 0 | AU32: 0 | AV32: 0 | AW32: 0 | AX32: 0 | AY32: 0 | AZ32: 0 | BA32: . | BB32: . | BC32: . | BD32: . | BE32: . | BF32: . | BG32: . | BH32: .
A33: AMAZONAS | B33: BONGARA | C33: CUISPES | D33: 010305 | E33: 638 | F33: . | G33: . | H33: . | I33: 0 | J33: 0 | K33: 0 | L33: 0 | M33: 0 | N33: 0 | O33: 0 | P33: 0 | Q33: 0 | R33: 0 | S33: 0 | T33: 0 | U33: 0 | V33: 0 | W33: 0 | X33: 0 | Y33: 0 | Z33: 0 | AA33: 0 | AB33: 0 | AC33: 0 | AD33: 0 | AE33: 0 | AF33: 0 | AG33: 0 | AH33: 0 | AI33: 0 | AJ33: 0 | AK33: 0 | AL33: 0 | AM33: 0 | AN33: 0 | AO33: 0 | AP33: 0 | AQ33: 0 | AR33: 0 | AS33: 0 | AT33: 0 | AU33: 0 | AV33: 0 | AW33: 0 | AX33: 0 | AY33: 0 | AZ33: 0 | BA33: . | BB33: . | BC33: . | BD33: . | BE33: . | BF33: . | BG33: . | BH33: .
A34: AMAZONAS | B34: BONGARA | C34: FLORIDA | D34: 010306 | E34: 6283 | F34: 13 | G34: 8.247031 | H34: 0.634387 | I34: 0 | J34: 0 | K34: 0 | L34: 0 | M34: 0 | N34: 0 | O34: 0 | P34: 0 | Q34: 0 | R34: 0 | S34: 0 | T34: 0 | U34: 0 | V34: 0 | W34: 0 | X34: 0 | Y34: 0 | Z34: 0 | AA34: 0 | AB34: 0 | AC34: 4664.31 | AD34: 0 | AE34: 0 | AF34: 4664.31 | AG34: 0 | AH34: 0 | AI34: 755.13 | AJ34: 0 | AK34: 0 | AL34: 755.13 | AM34: 0 | AN34: 0 | AO34: 798.2 | AP34: 0 | AQ34: 0 | AR34: 798.2 | AS34: 0 | AT34: 0 | AU34: 778.74 | AV34: 0 | AW34: 0 | AX34: 778.74 | AY34: 6996.38 | AZ34: 0 | BA34: 0 | BB34: 0 | BC34: 0 | BD34: 0 | BE34: 0 | BF34: 41 | BG34: 1723.0634 | BH34: 920.1
A35: AMAZONAS | B35: BONGARA | C35: JAZAN | D35: 010307 | E35: 7588 | F35: 52 | G35: 32.85964 | H35: 0.631916 | I35: 0 | J35: 0 | K35: 0 | L35: 0 | M35: 0 | N35: 0 | O35: 0 | P35: 0 | Q35: 0 | R35: 0 | S35: 0 | T35: 0 | U35: 0 | V35: 0 | W35: 0 | X35: 0 | Y35: 0 | Z35: 0 | AA35: 15420.09 | AB35: 0 | AC35: 25007.7 | AD35: 0 | AE35: 0 | AF35: 40427.79 | AG35: 3181.38 | AH35: 0 | AI35: 3548.74 | AJ35: 0 | AK35: 0 | AL35: 6730.12 | AM35: 166.2 | AN35: 0 | AO35: 3236.57 | AP35: 0 | AQ35: 0 | AR35: 3402.77 | AS35: 1058.44 | AT35: 0 | AU35: 1164.89 | AV35: 0 | AW35: 0 | AX35: 2223.33 | AY35: 52784.01 | AZ35: 0 | BA35: 5 | BB35: 12832.9 | BC35: 64164.5 | BD35: 0 | BE35: 55.933 | BF35: 99 | BG35: 1213.9783 | BH35: 825.876
A36: AMAZONAS | B36: BONGARA | C36: RECTA | D36: 010308 | E36: 208 | F36: . | G36: . | H36: . | I36: 0 | J36: 0 | K36: 0 | L36: 0 | M36: 0 | N36: 0 | O36: 0 | P36: 0 | Q36: 0 | R36: 0 | S36: 0 | T36: 0 | U36: 0 | V36: 0 | W36: 0 | X36: 0 | Y36: 0 | Z36: 0 | AA36: 0 | AB36: 0 | AC36: 0 | AD36: 0 | AE36: 0 | AF36: 0 | AG36: 0 | AH36: 0 | AI36: 0 | AJ36: 0 | AK36: 0 | AL36: 0 | AM36: 0 | AN36: 0 | AO36: 0 | AP36: 0 | AQ36: 0 | AR36: 0 | AS36: 0 | AT36: 0 | AU36: 0 | AV36: 0 | AW36: 0 | AX36: 0 | AY36: 0 | AZ36: 0 | BA36: . | BB36: . | BC36: . | BD36: . | BE36: . | BF36: . | BG36: . | BH36: .
A37: AMAZONAS | B37: BONGARA | C37: SAN CARLOS | D37: 010309 | E37: 606 | F37: . | G37: . | H37: . | I37: 0 | J37: 0 | K37: 0 | L37: 0 | M37: 0 | N37: 0 | O37: 0 | P37: 0 | Q37: 0 | R37: 0 | S37: 0 | T37: 0 | U37: 0 | V37: 0 | W37: 0 | X37: 0 | Y37: 0 | Z37: 0 | AA37: 0 | AB37: 0 | AC37: 0 | AD37: 0 | AE37: 0 | AF37: 0 | AG37: 0 | AH37: 0 | AI37: 0 | AJ37: 0 | AK37: 0 | AL37: 0 | AM37: 0 | AN37: 0 | AO37: 0 | AP37: 0 | AQ37: 0 | AR37: 0 | AS37: 0 | AT37: 0 | AU37: 0 | AV37: 0 | AW37: 0 | AX37: 0 | AY37: 0 | AZ37: 0 | BA37: . | BB37: . | BC37: . | BD37: . | BE37: . | BF37: . | BG37: . | BH37: .
A38: AMAZONAS | B38: BONGARA | C38: SHIPASBAMBA | D38: 010310 | E38: 1748 | F38: . | G38: . | H38: . | I38: 0 | J38: 0 | K38: 0 | L38: 0 | M38: 0 | N38: 0 | O38: 0 | P38: 0 | Q38: 0 | R38: 0 | S38: 0 | T38: 0 | U38: 0 | V38: 0 | W38: 0 | X38: 0 | Y38: 0 | Z38: 0 | AA38: 0 | AB38: 0 | AC38: 0 | AD38: 0 | AE38: 0 | AF38: 0 | AG38: 0 | AH38: 0 | AI38: 0 | AJ38: 0 | AK38: 0 | AL38: 0 | AM38: 0 | AN38: 0 | AO38: 0 | AP38: 0 | AQ38: 0 | AR38: 0 | AS38: 0 | AT38: 0 | AU38: 0 | AV38: 0 | AW38: 0 | AX38: 0 | AY38: 0 | AZ38: 0 | BA38: 0 | BB38: 0 | BC38: 0 | BD38: 0 | BE38: 0 | BF38: 6 | BG38: 27661.58 | BH38: 0
A39: AMAZONAS | B39: BONGARA | C39: VALERA | D39: 010311 | E39: 715 | F39: 1 | G39: 0.70735 | H39: 0.70735 | I39: 0 | J39: 0 | K39: 0 | L39: 0 | M39: 0 | N39: 0 | O39: 0 | P39: 0 | Q39: 0 | R39: 0 | S39: 0 | T39: 0 | U39: 0 | V39: 0 | W39: 0 | X39: 0 | Y39: 0 | Z39: 0 | AA39: 0 | AB39: 0 | AC39: 0 | AD39: 0 | AE39: 0 | AF39: 0 | AG39: 0 | AH39: 0 | AI39: 0 | AJ39: 0 | AK39: 0 | AL39: 0 | AM39: 0 | AN39: 0 | AO39: 0 | AP39: 0 | AQ39: 0 | AR39: 0 | AS39: 0 | AT39: 0 | AU39: 0 | AV39: 0 | AW39: 0 | AX39: 0 | AY39: 0 | AZ39: 0 | BA39: 0 | BB39: 0 | BC39: 0 | BD39: 0 | BE39: 0 | BF39: 6 | BG39: 0 | BH39: 0
A40: AMAZONAS | B40: BONGARA | C40: YAMBRASBAMBA | D40: 010312 | E40: 5513 | F40: . | G40: . | H40: . | I40: 0 | J40: 0 | K40: 0 | L40: 0 | M40: 0 | N40: 0 | O40: 0 | P40: 0 | Q40: 0 | R40: 0 | S40: 0 | T40: 0 | U40: 0 | V40: 0 | W40: 0 | X40: 0 | Y40: 0 | Z40: 0 | AA40: 0 | AB40: 0 | AC40: 0 | AD40: 0 | AE40: 0 | AF40: 0 | AG40: 0 | AH40: 0 | AI40: 0 | AJ40: 0 | AK40: 0 | AL40: 0 | AM40: 0 | AN40: 0 | AO40: 0 | AP40: 0 | AQ40: 0 | AR40: 0 | AS40: 0 | AT40: 0 | AU40: 0 | AV40: 0 | AW40: 0 | AX40: 0 | AY40: 0 | AZ40: 0 | BA40: 0 | BB40: 0 | BC40: 0 | BD40: 0 | BE40: 0 | BF40: 33 | BG40: 12.272727 | BH40: 0
...

Sheet Fuentes y conceptos
B2: PILAR | C2: FUENTE | D2: INFORMACIÓN | E2: BASE DE DATOS | F2: VARIABLE | G2: CONCEPTO
B3: Tamaño de mercado PYME | C3: CENEC ajustado con CCNN | D3: Privada | E3: censo_cenec | F3: nro_emp_cenec_corr | G3: Número de empresas (pymes con ventas anuales entre 180 mil y 5 millones al 2024) del Censo Económico Anual Corregido
B4: Tamaño de mercado PYME | C4: CENEC ajustado con CCNN | D4: Privada | E4: censo_cenec | F4: ventas_tot_soles_cenec_corr | G4: Ventas totales de empresas (pymes con ventas anuales entre 180 mil y 5 millones al 2024) del Censo Económico Anual Corregido
B5: Tamaño de mercado PYME | C5: CENEC ajustado con CCNN | D5: Privada | E5: censo_cenec | F5: ventas_prom_soles_cenec_corr | G5: Ventas promedio de empresas (pymes con ventas anuales entre 180 mil y 5 millones al 2024) del Censo Económico Anual Corregido
B6: Tamaño de mercado PYME | C6: RT | D6: Privada | E6: t_bpe_univ_venta_rt_datamart_version5, t_bpe_sunat_vars | F6: nro_emp_rt | G6: Número de empresas (pymes con ventas mensuales entre 3 mil y 416 mil) que reportan Recaudación Tributaria
B7: Tamaño de mercado PYME | C7: RT | D7: Privada | E7: t_bpe_univ_venta_rt_datamart_version5, t_bpe_sunat_vars | F7: ventas_tot_rt | G7: Ventas totales de empresas (pymes con ventas mensuales entre 3 mil y 416 mil) que reportan Recaudación Tributaria en ios últimos 12 meses
B8: Tamaño de mercado PYME | C8: RT | D8: Privada | E8: t_bpe_univ_venta_rt_datamart_version5, t_bpe_sunat_vars | F8: ventas_prom_rt | G8: Ventas promedio de empresas (pymes con ventas mensuales entre 3 mil y 416 mil) que reportan Recaudación Tributaria en los últimos 12 meses
B9: Tamaño de mercado PYME | C9: RT | D9: Privada | E9: t_bpe_univ_venta_rt_datamart_version5, t_bpe_bn_universo_accionable, t_bpe_bn_clientes, t_bpe_sunat_vars | F9: nro_emp_rt_acc | G9: Número de empresas (pyme) con RT dentro del universo accionable
B10: Tamaño de mercado PYME | C10: RT | D10: Privada | E10: t_bpe_univ_venta_rt_datamart_version5, t_bpe_bn_universo_accionable, t_bpe_bn_clientes, t_bpe_sunat_vars | F10: ventas_tot_rt_acc | G10: Ventas totales de empresas (pyme) con RT dentro del universo accionable
B11: Tamaño de mercado PYME | C11: RT | D11: Privada | E11: t_bpe_univ_venta_rt_datamart_version5, t_bpe_bn_universo_accionable, t_bpe_bn_clientes, t_bpe_sunat_vars | F11: ventas_prom_rt_acc | G11: Ventas promedio de empresas (pyme) con RT dentro del universo accionable
B12: Penetración financiera PYME | C12: SBS | D12: Pública | E12: Carpeta de Información Financiera: https://www.sbs.gob.pe/app/stats_net/stats/EstadisticaBoletinEstadistico.aspx?p=14# | F12: peq_emp_tot_sbs | G12: Colocaciones de crédito de pequeñas empresas de la Superintendencia de Banca y Seguros
B13: Penetración financiera PYME | C13: SBS | D13: Pública | E13: Carpeta de Información Financiera: https://www.sbs.gob.pe/app/stats_net/stats/EstadisticaBoletinEstadistico.aspx?p=14# | F13: micro_emp_tot_sbs | G13: Colocaciones de crédito de microempresas de la Superintendencia de Banca y Seguros
... B25: Transaccionalidad Intercorp | C25: IBK | D25: Privada | E25: Se coordinó con Rodrigo Cornejo (IBK) | F25: tickets_unicos_transac_retail | G25: Tickets unicos del total de empresas del grupo Intercorp

Sheet Tablas
B2: TABLAS UTILIZADAS PARA EL INDICE | C2: RESPONSABLE TABLA | D2: RESPONSABLE LÓGICA
B3: censo_cenec | C3: Mauricio Aldana (AC), Adriana Bravo (AC) | D3: Mauricio Aldana (AC)
B4: t_bpe_univ_venta_rt_datamart_version5 | C4: Mauricio Aldana (AC), Adriana Bravo (AC) | D4: Edson Apari (IBK), Jose Barboza (IBK), Jenny Espinoza (IBK)
B5: t_bpe_sunat_vars | C5: Mauricio Aldana (AC), Adriana Bravo (AC) | D5: Edson Apari (IBK), Jenny Espinoza (IBK)
B6: t_bpe_bn_universo_accionable | C6: Mauricio Aldana (AC), Adriana Bravo (AC) | D6: Edson Apari (IBK), Jenny Espinoza (IBK)
B7: t_bpe_bn_clientes | C7: Mauricio Aldana (AC), Adriana Bravo (AC) | D7: Edson Apari (IBK), Jenny Espinoza (IBK)
B8: t_bpe_base_universo_sunat_variables | C8: Mauricio Aldana (AC), Adriana Bravo (AC) | D8: Edson Apari (IBK), Jose Barboza (IBK), Jenny Espinoza (IBK)
B9: t_bpe_brainstorn_vars_plin | C9: Mauricio Aldana (AC), Adriana Bravo (AC) | D9: Edson Apari (IBK), Jose Barboza (IBK), Jenny Espinoza (IBK)
B10: t_bpe_base_izipay_v2 | C10: Mauricio Aldana (AC), Adriana Bravo (AC) | D10: Edson Apari (IBK), Jose Barboza (IBK), Jenny Espinoza (IBK)

Sheet BaseIBK distritos filt
A1: departamento | B1: provincia | C1: distrito | D1: ubigeo | E1: nro_emp_cenec_corr | F1: ventas_tot_soles_cenec_corr | G1: ventas_prom_soles_cenec_corr | H1: nro_emp_rt | I1: ventas_tot_rt | J1: ventas_prom_rt | K1: nro_emp_rt_acc | L1: ventas_tot_rt_acc | M1: ventas_prom_rt_acc | N1: peq_emp_tot_sbs | O1: micro_emp_tot_sbs | P1: mto_desembolso_con_garantia_rcc | Q1: pct_rt_clf_normal_acc | R1: mto_deuda_rt_rcc | S1: mto_deuda_no_vigente_rt_rcc | T1: saldo_no_moroso_rt_rcc | U1: n_univ_tot_transac | V1: plin_univ_tot_transac | W1: izipay_univ_tot_transac | X1: n_univ_tot_transac_acc | Y1: plin_univ_tot_transac_acc | Z1: izipay_univ_tot_transac_acc | AA1: usuarios_unicos_transac_retail | AB1: mto_tot_transac_retail | AC1: tickets_unicos_transac_retail | AD1: nro_emp_cenec_corr_est | AE1: ventas_tot_mill_soles_cenec_corr_est | AF1: ventas_prom_mill_soles_cenec_corr_est | AG1: nro_emp_rt_est | AH1: ventas_tot_rt_est | AI1: ventas_prom_rt_est | AJ1: nro_emp_rt_acc_est | AK1: ventas_tot_rt_acc_est | AL1: ventas_prom_rt_acc_est | AM1: peq_emp_tot_sbs_est | AN1: micro_emp_tot_sbs_est | AO1: mto_desembolso_con_garantia_rcc_est | AP1: pct_rt_clf_normal_acc_est | AQ1: pct_rt_clf_normal_acc_est_imp | AR1: saldo_no_moroso_rt_rcc_est | AS1: saldo_no_moroso_rt_rcc_est_imp | AT1: n_univ_tot_transac_est | AU1: plin_univ_tot_transac_est | AV1: izipay_univ_tot_transac_est | AW1: n_univ_tot_transac_acc_est | AX1: plin_univ_tot_transac_acc_est | AY1: izipay_univ_tot_transac_acc_est | AZ1: usuarios_unicos_transac_retail_est | BA1: mto_tot_transac_retail_est | BB1: tickets_unicos_transac_retail_est | BC1: # Empresas (miles) | BD1: Venta prom. mensual predic (miles S/) | BE1: # Clusters | BF1: # EE en clusters (miles)
A2: ÁNCASH | B2: HUARAZ | C2: HUARAZ | D2: 020101 | E2: 1260 | F2: 863.40381 | G2: 0.68524112 | H2: 175 | I2: 8529090.5 | J2: 48737.66 | K2: 171 | L2: 8493779 | M2: 49671 | N2: 600701.75 | O2: 64169.59 | P2: 540976.33 | Q2: 0.88 | R2: 21062445 | S2: 349017.76 | T2: =IF((100-IFERROR(S2/R2*100,0))=100,50,(100-IFERROR(S2/R2*100,0))) -> 98.342938 | U2: 11028 | V2: 32727804 | W2: 5155097.8 | X2: 4184 | Y2: 19399919 | Z2: 3831949 | AA2: 333315 | AB2: 28214412 | AC2: 665818 | AD2: =(E2-MIN($E$2:$E$170))/(MAX($E$2:$E$170)-MIN($E$2:$E$170))*100 -> 8.6390858 | AE2: =(F2-MIN($F$2:$F$170))/(MAX($F$2:$F$170)-MIN($F$2:$F$170))*100 -> 7.6143093 | AF2: =(G2-MIN($G$2:$G$170))/(MAX($G$2:$G$170)-MIN($G$2:$G$170))*100 -> 29.289786 | AG2: =(H2-MIN($H$2:$H$170))/(MAX($H$2:$H$170)-MIN($H$2:$H$170))*100 -> 8.5532747 | AH2: =(I2-MIN($I$2:$I$170))/(MAX($I$2:$I$170)-MIN($I$2:$I$170))*100 -> 6.3857732 | AI2: =(J2-MIN($J$2:$J$170))/(MAX($J$2:$J$170)-MIN($J$2:$J$170))*100 -> 24.778348 | AJ2: =(K2-MIN($K$2:$K$170))/(MAX($K$2:$K$170)-MIN($K$2:$K$170))*100 -> 8.5843373 | AK2: =(L2-MIN($L$2:$L$170))/(MAX($L$2:$L$170)-MIN($L$2:$L$170))*100 -> 6.5586593 | AL2: =(M2-MIN($M$2:$M$170))/(MAX($M$2:$M$170)-MIN($M$2:$M$170))*100 -> 25.252803 | AM2: =(N2-MIN($N$2:$N$170))/(MAX($N$2:$N$170)-MIN($N$2:$N$170))*100 -> 6.4324178 | AN2: =(O2-MIN($O$2:$O$170))/(MAX($O$2:$O$170)-MIN($O$2:$O$170))*100 -> 23.771508 | AO2: =(P2-MIN($P$2:$P$170))/(MAX($P$2:$P$170)-MIN($P$2:$P$170))*100 -> 2.1982418 | AP2: =(Q2-MIN($Q$2:$Q$170))/(MAX($Q$2:$Q$170)-MIN($Q$2:$Q$170))*100 -> 88 | AQ2: =IF(AP2>=50,AP2,50) -> 88 | AR2: =(#REF!-MIN(#REF!))/(MAX(#REF!)-MIN(#REF!))*100 -> #REF! | AS2: =IF(AR2>=50,AR2,50) -> #REF! | AT2: =(U2-MIN($U$2:$U$170))/(MAX($U$2:$U$170)-MIN($U$2:$U$170))*100 -> 11.456319 | AU2: =(V2-MIN($V$2:$V$170))/(MAX($V$2:$V$170)-MIN($V$2:$V$170))*100 -> 5.940696 | AV2: =(W2-MIN($W$2:$W$170))/(MAX($W$2:$W$170)-MIN($W$2:$W$170))*100 -> 0.50334453 | AW2: =(X2-MIN($X$2:$X$170))/(MAX($X$2:$X$170)-MIN($X$2:$X$170))*100 -> 10.955189 | AX2: =(Y2-MIN($Y$2:$Y$170))/(MAX($Y$2:$Y$170)-MIN($Y$2:$Y$170))*100 -> 6.0125993 | AY2: =(Z2-MIN($Z$2:$Z$170))/(MAX($Z$2:$Z$170)-MIN($Z$2:$Z$170))*100 -> 5.0852911 | AZ2: =(AA2-MIN($AA$2:$AA$170))/(MAX($AA$2:$AA$170)-MIN($AA$2:$AA$170))*100 -> 13.770633 | BA2: =(AB2-MIN($AB$2:$AB$170))/(MAX($AB$2:$AB$170)-MIN($AB$2:$AB$170))*100 -> 5.1169704 | BB2: =(AC2-MIN($AC$2:$AC$170))/(MAX($AC$2:$AC$170)-MIN($AC$2:$AC$170))*100 -> 10.787851 | BC2: 3.6 | BD2: 177803 | BE2: 1 | BF2: 1.5
A3: ÁNCASH | B3: HUARAZ | C3: INDEPENDENCIA | D3: 020105 | E3: 386 | F3: 254.47099 | G3: 0.65925128 | H3: 99 | I3: 4698551.5 | J3: 47460.116 | K3: 93 | L3: 4631298 | M3: 49799 | N3: 210.67 | O3: 745.7 | P3: 899549 | Q3: 0.92 | R3: 12813273 | S3: 313857.6 | T3: =IF((100-IFERROR(S3/R3*100,0))=100,50,(100-IFERROR(S3/R3*100,0))) -> 97.550528 | U3: 7395 | V3: 20063518 | W3: 1718822.1 | X3: 2710 | Y3: 11090637 | Z3: 1677749 | AA3: 121061 | AB3: 4283092.3 | AC3: 166717 | AD3: =(E3-MIN($E$2:$E$170))/(MAX($E$2:$E$170)-MIN($E$2:$E$170))*100 -> 2.6227026 | AE3: =(F3-MIN($F$2:$F$170))/(MAX($F$2:$F$170)-MIN($F$2:$F$170))*100 -> 2.2287588 | AF3: =(G3-MIN($G$2:$G$170))/(MAX($G$2:$G$170)-MIN($G$2:$G$170))*100 -> 26.999616 | AG3: =(H3-MIN($H$2:$H$170))/(MAX($H$2:$H$170)-MIN($H$2:$H$170))*100 -> 4.8387097 | AH3: =(I3-MIN($I$2:$I$170))/(MAX($I$2:$I$170)-MIN($I$2:$I$170))*100 -> 3.5178293 | AI3: =(J3-MIN($J$2:$J$170))/(MAX($J$2:$J$170)-MIN($J$2:$J$170))*100 -> 24.128842 | AJ3: =(K3-MIN($K$2:$K$170))/(MAX($K$2:$K$170)-MIN($K$2:$K$170))*100 -> 4.6686747 | AK3: =(L3-MIN($L$2:$L$170))/(MAX($L$2:$L$170)-MIN($L$2:$L$170))*100 -> 3.5761592 | AL3: =(M3-MIN($M$2:$M$170))/(MAX($M$2:$M$170)-MIN($M$2:$M$170))*100 -> 25.317878 | AM3: =(N3-MIN($N$2:$N$170))/(MAX($N$2:$N$170)-MIN($N$2:$N$170))*100 -> 0.0022558907 | AN3: =(O3-MIN($O$2:$O$170))/(MAX($O$2:$O$170)-MIN($O$2:$O$170))*100 -> 0.27624321 | AO3: =(P3-MIN($P$2:$P$170))/(MAX($P$2:$P$170)-MIN($P$2:$P$170))*100 -> 3.6552916 | AP3: =(Q3-MIN($Q$2:$Q$170))/(MAX($Q$2:$Q$170)-MIN($Q$2:$Q$170))*100 -> 92 | AQ3: =IF(AP3>=50,AP3,50) -> 92 | AR3: =(#REF!-MIN(#REF!))/(MAX(#REF!)-MIN(#REF!))*100 -> #REF! | AS3: =IF(AR3>=50,AR3,50) -> #REF! | AT3: =(U3-MIN($U$2:$U$170))/(MAX($U$2:$U$170)-MIN($U$2:$U$170))*100 -> 7.6584535 | AU3: =(V3-MIN($V$2:$V$170))/(MAX($V$2:$V$170)-MIN($V$2:$V$170))*100 -> 3.6337412 | AV3: =(W3-MIN($W$2:$W$170))/(MAX($W$2:$W$170)-MIN($W$2:$W$170))*100 -> 0.16781505 | AW3: =(X3-MIN($X$2:$X$170))/(MAX($X$2:$X$170)-MIN($X$2:$X$170))*100 -> 7.0744037 | AX3: =(Y3-MIN($Y$2:$Y$170))/(MAX($Y$2:$Y$170)-MIN($Y$2:$Y$170))*100 -> 3.4292184 | AY3: =(Z3-MIN($Z$2:$Z$170))/(MAX($Z$2:$Z$170)-MIN($Z$2:$Z$170))*100 -> 2.2263759 | AZ3: =(AA3-MIN($AA$2:$AA$170))/(MAX($AA$2:$AA$170)-MIN($AA$2:$AA$170))*100 -> 5.0000351 | BA3: =(AB3-MIN($AB$2:$AB$170))/(MAX($AB$2:$AB$170)-MIN($AB$2:$AB$170))*100 -> 0.77678231 | BB3: =(AC3-MIN($AC$2:$AC$170))/(MAX($AC$2:$AC$170)-MIN($AC$2:$AC$170))*100 -> 2.7004263 | BC3: 1.8 | BD3: 89333 | BE3: 1 | BF3: 0.1
A4: ÁNCASH | B4: SANTA | C4: CHIMBOTE | D4: 021801 | E4: 3654 | F4: 2466.8819 | G4: 0.67511821 | H4: 244 | I4: 9030336.2 | J4: 37009.575 | K4: 230 | L4: 8845937 | M4: 38461 | N4: 693819.75 | O4: 87302.61 | P4: 4130695.5 | Q4: 0.9 | R4: 39197774 | S4: 917640.58 | T4: =IF((100-IFERROR(S4/R4*100,0))=100,50,(100-IFERROR(S4/R4*100,0))) -> 97.658947 | U4: 20417 | V4: 1.1757502e+08 | W4: 6974034.3 | X4: 7125 | Y4: 64404735 | Z4: 5218361 | AA4: 914523 | AB4: 1.5742866e+08 | AC4: 2228745 | AD4: =(E4-MIN($E$2:$E$170))/(MAX($E$2:$E$170)-MIN($E$2:$E$170))*100 -> 25.118744 | AE4: =(F4-MIN($F$2:$F$170))/(MAX($F$2:$F$170)-MIN($F$2:$F$170))*100 -> 21.795861 | AF4: =(G4-MIN($G$2:$G$170))/(MAX($G$2:$G$170)-MIN($G$2:$G$170))*100 -> 28.397776 | AG4: =(H4-MIN($H$2:$H$170))/(MAX($H$2:$H$170)-MIN($H$2:$H$170))*100 -> 11.925709 | AH4: =(I4-MIN($I$2:$I$170))/(MAX($I$2:$I$170)-MIN($I$2:$I$170))*100 -> 6.7610584 | AI4: =(J4-MIN($J$2:$J$170))/(MAX($J$2:$J$170)-MIN($J$2:$J$170))*100 -> 18.815761 | AJ4: =(K4-MIN($K$2:$K$170))/(MAX($K$2:$K$170)-MIN($K$2:$K$170))*100 -> 11.546185 | AK4: =(L4-MIN($L$2:$L$170))/(MAX($L$2:$L$170)-MIN($L$2:$L$170))*100 -> 6.8305859 | AL4: =(M4-MIN($M$2:$M$170))/(MAX($M$2:$M$170)-MIN($M$2:$M$170))*100 -> 19.553624 | AM4: =(N4-MIN($N$2:$N$170))/(MAX($N$2:$N$170)-MIN($N$2:$N$170))*100 -> 7.4295414 | AN4: =(O4-MIN($O$2:$O$170))/(MAX($O$2:$O$170)-MIN($O$2:$O$170))*100 -> 32.341093 | AO4: =(P4-MIN($P$2:$P$170))/(MAX($P$2:$P$170)-MIN($P$2:$P$170))*100 -> 16.784963 | AP4: =(Q4-MIN($Q$2:$Q$170))/(MAX($Q$2:$Q$170)-MIN($Q$2:$Q$170))*100 -> 90 | AQ4: =IF(AP4>=50,AP4,50) -> 90 | AR4: =(#REF!-MIN(#REF!))/(MAX(#REF!)-MIN(#REF!))*100 -> #REF! | AS4: =IF(AR4>=50,AR4,50) -> #REF! | AT4: =(U4-MIN($U$2:$U$170))/(MAX($U$2:$U$170)-MIN($U$2:$U$170))*100 -> 21.271391 | AU4: =(V4-MIN($V$2:$V$170))/(MAX($V$2:$V$170)-MIN($V$2:$V$170))*100 -> 21.396655 | AV4: =(W4-MIN($W$2:$W$170))/(MAX($W$2:$W$170)-MIN($W$2:$W$170))*100 -> 0.68095158 | AW4: =(X4-MIN($X$2:$X$170))/(MAX($X$2:$X$170)-MIN($X$2:$X$170))*100 -> 18.698331 | AX4: =(Y4-MIN($Y$2:$Y$170))/(MAX($Y$2:$Y$170)-MIN($Y$2:$Y$170))*100 -> 20.004733 | AY4: =(Z4-MIN($Z$2:$Z$170))/(MAX($Z$2:$Z$170)-MIN($Z$2:$Z$170))*100 -> 6.9252476 | AZ4: =(AA4-MIN($AA$2:$AA$170))/(MAX($AA$2:$AA$170)-MIN($AA$2:$AA$170))*100 -> 37.786868 | BA4: =(AB4-MIN($AB$2:$AB$170))/(MAX($AB$2:$AB$170)-MIN($AB$2:$AB$170))*100 -> 28.551288 | BB4: =(AC4-MIN($AC$2:$AC$170))/(MAX($AC$2:$AC$170)-MIN($AC$2:$AC$170))*100 -> 36.113494 | BC4: 6.9 | BD4: 329218 | BE4: 1 | BF4: 0.8
A5: ÁNCASH | B5: SANTA | C5: SANTA | D5: 021808 | E5: 219 | F5: 156.61161 | G5: 0.7151215 | H5: 10 | I5: 419463 | J5: 41946.3 | K5: 9 | L5: 399038 | M5: 44338 | N5: 32714.98 | O5: 13743.23 | P5: 27564.27 | Q5: 1 | R5: 168449.04 | S5: 0 | T5: =IF((100-IFERROR(S5/R5*100,0))=100,50,(100-IFERROR(S5/R5*100,0))) -> 50 | U5: 1346 | V5: 4991034.9 | W5: 79579.203 | X5: 537 | Y5: 2196064 | Z5: 76166 | AA5: 21536 | AB5: 1140661.7 | AC5: 34456 | AD5: =(E5-MIN($E$2:$E$170))/(MAX($E$2:$E$170)-MIN($E$2:$E$170))*100 -> 1.473119 | AE5: =(F5-MIN($F$2:$F$170))/(MAX($F$2:$F$170)-MIN($F$2:$F$170))*100 -> 1.3632666 | AF5: =(G5-MIN($G$2:$G$170))/(MAX($G$2:$G$170)-MIN($G$2:$G$170))*100 -> 31.922781 | AG5: =(H5-MIN($H$2:$H$170))/(MAX($H$2:$H$170)-MIN($H$2:$H$170))*100 -> 0.48875855 | AH5: =(I5-MIN($I$2:$I$170))/(MAX($I$2:$I$170)-MIN($I$2:$I$170))*100 -> 0.31405407 | AI5: =(J5-MIN($J$2:$J$170))/(MAX($J$2:$J$170)-MIN($J$2:$J$170))*100 -> 21.325604 | AJ5: =(K5-MIN($K$2:$K$170))/(MAX($K$2:$K$170)-MIN($K$2:$K$170))*100 -> 0.45180723 | AK5: =(L5-MIN($L$2:$L$170))/(MAX($L$2:$L$170)-MIN($L$2:$L$170))*100 -> 0.30812602 | AL5: =(M5-MIN($M$2:$M$170))/(MAX($M$2:$M$170)-MIN($M$2:$M$170))*100 -> 22.541498 | AM5: =(N5-MIN($N$2:$N$170))/(MAX($N$2:$N$170)-MIN($N$2:$N$170))*100 -> 0.35031764 | AN5: =(O5-MIN($O$2:$O$170))/(MAX($O$2:$O$170)-MIN($O$2:$O$170))*100 -> 5.0911545 | AO5: =(P5-MIN($P$2:$P$170))/(MAX($P$2:$P$170)-MIN($P$2:$P$170))*100 -> 0.11200662 | AP5: =(Q5-MIN($Q$2:$Q$170))/(MAX($Q$2:$Q$170)-MIN($Q$2:$Q$170))*100 -> 100 | AQ5: =IF(AP5>=50,AP5,50) -> 100 | AR5: =(#REF!-MIN(#REF!))/(MAX(#REF!)-MIN(#REF!))*100 -> #REF! | AS5: =IF(AR5>=50,AR5,50) -> #REF! | AT5: =(U5-MIN($U$2:$U$170))/(MAX($U$2:$U$170)-MIN($U$2:$U$170))*100 -> 1.3349502 | AU5: =(V5-MIN($V$2:$V$170))/(MAX($V$2:$V$170)-MIN($V$2:$V$170))*100 -> 0.88810407 | AV5: =(W5-MIN($W$2:$W$170))/(MAX($W$2:$W$170)-MIN($W$2:$W$170))*100 -> 0.0077538784 | AW5: =(X5-MIN($X$2:$X$170))/(MAX($X$2:$X$170)-MIN($X$2:$X$170))*100 -> 1.3532726 | AX5: =(Y5-MIN($Y$2:$Y$170))/(MAX($Y$2:$Y$170)-MIN($Y$2:$Y$170))*100 -> 0.66386874 | AY5: =(Z5-MIN($Z$2:$Z$170))/(MAX($Z$2:$Z$170)-MIN($Z$2:$Z$170))*100 -> 0.10085831 | AZ5: =(AA5-MIN($AA$2:$AA$170))/(MAX($AA$2:$AA$170)-MIN($AA$2:$AA$170))*100 -> 0.88753888 | BA5: =(AB5-MIN($AB$2:$AB$170))/(MAX($AB$2:$AB$170)-MIN($AB$2:$AB$170))*100 -> 0.2068706 | BB5: =(AC5-MIN($AC$2:$AC$170))/(MAX($AC$2:$AC$170)-MIN($AC$2:$AC$170))*100 -> 0.5572712 | BC5: 0.4 | BD5: 14906 | BE5: 0 | BF5: 0
A6: ÁNCASH | B6: SANTA | C6: NUEVO CHIMBOTE | D6: 021809 | E6: 1283 | F6: 793.45951 | G6: 0.61844078 | H6: 192 | I6: 8032436.9 | J6: 41835.609 | K6: 182 | L6: 7502707 | M6: 41224 | N6: 90087.98 | O6: 42786.87 | P6: 986851.98 | Q6: 0.86 | R6: 27799107 | S6: 959122.83 | T6: =IF((100-IFERROR(S6/R6*100,0))=100,50,(100-IFERROR(S6/R6*100,0))) -> 96.549807 | U6: 12682 | V6: 72835949 | W6: 2842055 | X6: 4440 | Y6: 38047143 | Z6: 2535451 | AA6: 304452 | AB6: 19344675 | AC6: 621856 | AD6: =(E6-MIN($E$2:$E$170))/(MAX($E$2:$E$170)-MIN($E$2:$E$170))*100 -> 8.7974117 | AE6: =(F6-MIN($F$2:$F$170))/(MAX($F$2:$F$170)-MIN($F$2:$F$170))*100 -> 6.9957049 | AF6: =(G6-MIN($G$2:$G$170))/(MAX($G$2:$G$170)-MIN($G$2:$G$170))*100 -> 23.403481 | AG6: =(H6-MIN($H$2:$H$170))/(MAX($H$2:$H$170)-MIN($H$2:$H$170))*100 -> 9.3841642 | AH6: =(I6-MIN($I$2:$I$170))/(MAX($I$2:$I$170)-MIN($I$2:$I$170))*100 -> 6.0139262 | AI6: =(J6-MIN($J$2:$J$170))/(MAX($J$2:$J$170)-MIN($J$2:$J$170))*100 -> 21.269328 | AJ6: =(K6-MIN($K$2:$K$170))/(MAX($K$2:$K$170)-MIN($K$2:$K$170))*100 -> 9.1365462 | AK6: =(L6-MIN($L$2:$L$170))/(MAX($L$2:$L$170)-MIN($L$2:$L$170))*100 -> 5.7933812 | AL6: =(M6-MIN($M$2:$M$170))/(MAX($M$2:$M$170)-MIN($M$2:$M$170))*100 -> 20.958337 | AM6: =(N6-MIN($N$2:$N$170))/(MAX($N$2:$N$170)-MIN($N$2:$N$170))*100 -> 0.96467761 | AN6: =(O6-MIN($O$2:$O$170))/(MAX($O$2:$O$170)-MIN($O$2:$O$170))*100 -> 15.850318 | AO6: =(P6-MIN($P$2:$P$170))/(MAX($P$2:$P$170)-MIN($P$2:$P$170))*100 -> 4.0100448 | AP6: =(Q6-MIN($Q$2:$Q$170))/(MAX($Q$2:$Q$170)-MIN($Q$2:$Q$170))*100 -> 86 | AQ6: =IF(AP6>=50,AP6,50) -> 86 | AR6: =(#REF!-MIN(#REF!))/(MAX(#REF!)-MIN(#REF!))*100 -> #REF! | AS6: =IF(AR6>=50,AR6,50) -> #REF! | AT6: =(U6-MIN($U$2:$U$170))/(MAX($U$2:$U$170)-MIN($U$2:$U$170))*100 -> 13.185377 | AU6: =(V6-MIN($V$2:$V$170))/(MAX($V$2:$V$170)-MIN($V$2:$V$170))*100 -> 13.246885 | AV6: =(W6-MIN($W$2:$W$170))/(MAX($W$2:$W$170)-MIN($W$2:$W$170))*100 -> 0.27749128 | AW6: =(X6-MIN($X$2:$X$170))/(MAX($X$2:$X$170)-MIN($X$2:$X$170))*100 -> 11.629193 | AX6: =(Y6-MIN($Y$2:$Y$170))/(MAX($Y$2:$Y$170)-MIN($Y$2:$Y$170))*100 -> 11.810078 | AY6: =(Z6-MIN($Z$2:$Z$170))/(MAX($Z$2:$Z$170)-MIN($Z$2:$Z$170))*100 -> 3.3646626 | AZ6: =(AA6-MIN($AA$2:$AA$170))/(MAX($AA$2:$AA$170)-MIN($AA$2:$AA$170))*100 -> 12.577978 | BA6: =(AB6-MIN($AB$2:$AB$170))/(MAX($AB$2:$AB$170)-MIN($AB$2:$AB$170))*100 -> 3.5083535 | BB6: =(AC6-MIN($AC$2:$AC$170))/(MAX($AC$2:$AC$170)-MIN($AC$2:$AC$170))*100 -> 10.075491 | BC6: 3.4 | BD6: 159822 | BE6: 0 | BF6: 0
A7: AREQUIPA | B7: AREQUIPA | C7: AREQUIPA | D7: 040101 | E7: 5653 | F7: 4304.0976 | G7: 0.76138291 | H7: 405 | I7: 20257213 | J7: 50017.81 | K7: 398 | L7: 19791174 | M7: 49727 | N7: 2134572.3 | O7: 94891.91 | P7: 3938302.9 | Q7: 0.91 | R7: 79958060 | S7: 1240509.8 | T7: =IF((100-IFERROR(S7/R7*100,0))=100,50,(100-IFERROR(S7/R7*100,0))) -> 98.448549 | U7: 26484 | V7: 71212946 | W7: 31821439 | X7: 11688 | Y7: 44479129 | Z7: 23010710 | AA7: 1017839 | AB7: 1.241172e+08 | AC7: 1774640 | AD7: =(E7-MIN($E$2:$E$170))/(MAX($E$2:$E$170)-MIN($E$2:$E$170))*100 -> 38.879328 | AE7: =(F7-MIN($F$2:$F$170))/(MAX($F$2:$F$170)-MIN($F$2:$F$170))*100 -> 38.044645 | AF7: =(G7-MIN($G$2:$G$170))/(MAX($G$2:$G$170)-MIN($G$2:$G$170))*100 -> 35.999238 | AG7: =(H7-MIN($H$2:$H$170))/(MAX($H$2:$H$170)-MIN($H$2:$H$170))*100 -> 19.794721 | AH7: =(I7-MIN($I$2:$I$170))/(MAX($I$2:$I$170)-MIN($I$2:$I$170))*100 -> 15.166678 | AI7: =(J7-MIN($J$2:$J$170))/(MAX($J$2:$J$170)-MIN($J$2:$J$170))*100 -> 25.42918 | AJ7: =(K7-MIN($K$2:$K$170))/(MAX($K$2:$K$170)-MIN($K$2:$K$170))*100 -> 19.97992 | AK7: =(L7-MIN($L$2:$L$170))/(MAX($L$2:$L$170)-MIN($L$2:$L$170))*100 -> 15.282193 | AL7: =(M7-MIN($M$2:$M$170))/(MAX($M$2:$M$170)-MIN($M$2:$M$170))*100 -> 25.281273 | AM7: =(N7-MIN($N$2:$N$170))/(MAX($N$2:$N$170)-MIN($N$2:$N$170))*100 -> 22.857368 | AN7: =(O7-MIN($O$2:$O$170))/(MAX($O$2:$O$170)-MIN($O$2:$O$170))*100 -> 35.152535 | AO7: =(P7-MIN($P$2:$P$170))/(MAX($P$2:$P$170)-MIN($P$2:$P$170))*100 -> 16.003181 | AP7: =(Q7-MIN($Q$2:$Q$170))/(MAX($Q$2:$Q$170)-MIN($Q$2:$Q$170))*100 -> 91 | AQ7: =IF(AP7>=50,AP7,50) -> 91 | AR7: =(#REF!-MIN(#REF!))/(MAX(#REF!)-MIN(#REF!))*100 -> #REF! | AS7: =IF(AR7>=50,AR7,50) -> #REF! | AT7: =(U7-MIN($U$2:$U$170))/(MAX($U$2:$U$170)-MIN($U$2:$U$170))*100 -> 27.613711 | AU7: =(V7-MIN($V$2:$V$170))/(MAX($V$2:$V$170)-MIN($V$2:$V$170))*100 -> 12.951236 | AV7: =(W7-MIN($W$2:$W$170))/(MAX($W$2:$W$170)-MIN($W$2:$W$170))*100 -> 3.1071355 | AW7: =(X7-MIN($X$2:$X$170))/(MAX($X$2:$X$170)-MIN($X$2:$X$170))*100 -> 30.711916 | AX7: =(Y7-MIN($Y$2:$Y$170))/(MAX($Y$2:$Y$170)-MIN($Y$2:$Y$170))*100 -> 13.809801 | AY7: =(Z7-MIN($Z$2:$Z$170))/(MAX($Z$2:$Z$170)-MIN($Z$2:$Z$170))*100 -> 30.538105 | AZ7: =(AA7-MIN($AA$2:$AA$170))/(MAX($AA$2:$AA$170)-MIN($AA$2:$AA$170))*100 -> 42.056013 | BA7: =(AB7-MIN($AB$2:$AB$170))/(MAX($AB$2:$AB$170)-MIN($AB$2:$AB$170))*100 -> 22.509916 | BB7: =(AC7-MIN($AC$2:$AC$170))/(MAX($AC$2:$AC$170)-MIN($AC$2:$AC$170))*100 -> 28.755184 | BC7: 11 | BD7: 566439 | BE7: 6 | BF7: 6.3
A8: AREQUIPA | B8: AREQUIPA | C8: ALTO SELVA ALEGRE | D8: 040102 | E8: 402 | F8: 208.9648 | G8: 0.51981294 | H8: 68 | I8: 3132970.9 | J8: 46073.102 | K8: 66 | L8: 3098338 | M8: 46945 | N8: 109611.04 | O8: 17729.58 | P8: 731979.01 | Q8: 0.88 | R8: 10108848 | S8: 331016.99 | T8: =IF((100-IFERROR(S8/R8*100,0))=100,50,(100-IFERROR(S8/R8*100,0))) -> 96.725473 | U8: 7179 | V8: 17263943 | W8: 1829225.6 | X8: 3081 | Y8: 10972276 | Z8: 728505 | AA8: 88323 | AB8: 5164659.9 | AC8: 158054 | AD8: =(E8-MIN($E$2:$E$170))/(MAX($E$2:$E$170)-MIN($E$2:$E$170))*100 -> 2.7328423 | AE8: =(F8-MIN($F$2:$F$170))/(MAX($F$2:$F$170)-MIN($F$2:$F$170))*100 -> 1.826291 | AF8: =(G8-MIN($G$2:$G$170))/(MAX($G$2:$G$170)-MIN($G$2:$G$170))*100 -> 14.712605 | AG8: =(H8-MIN($H$2:$H$170))/(MAX($H$2:$H$170)-MIN($H$2:$H$170))*100 -> 3.3235582 | AH8: =(I8-MIN($I$2:$I$170))/(MAX($I$2:$I$170)-MIN($I$2:$I$170))*100 -> 2.3456712 | AI8: =(J8-MIN($J$2:$J$170))/(MAX($J$2:$J$170)-MIN($J$2:$J$170))*100 -> 23.42368 | AJ8: =(K8-MIN($K$2:$K$170))/(MAX($K$2:$K$170)-MIN($K$2:$K$170))*100 -> 3.313253 | AK8: =(L8-MIN($L$2:$L$170))/(MAX($L$2:$L$170)-MIN($L$2:$L$170))*100 -> 2.3924502 | AL8: =(M8-MIN($M$2:$M$170))/(MAX($M$2:$M$170)-MIN($M$2:$M$170))*100 -> 23.866901 | AM8: =(N8-MIN($N$2:$N$170))/(MAX($N$2:$N$170)-MIN($N$2:$N$170))*100 -> 1.1737339 | AN8: =(O8-MIN($O$2:$O$170))/(MAX($O$2:$O$170)-MIN($O$2:$O$170))*100 -> 6.5678906 | AO8: =(P8-MIN($P$2:$P$170))/(MAX($P$2:$P$170)-MIN($P$2:$P$170))*100 -> 2.9743758 | AP8: =(Q8-MIN($Q$2:$Q$170))/(MAX($Q$2:$Q$170)-MIN($Q$2:$Q$170))*100 -> 88 | AQ8: =IF(AP8>=50,AP8,50) -> 88 | AR8: =(#REF!-MIN(#REF!))/(MAX(#REF!)-MIN(#REF!))*100 -> #REF! | AS8: =IF(AR8>=50,AR8,50) -> #REF! | AT8: =(U8-MIN($U$2:$U$170))/(MAX($U$2:$U$170)-MIN($U$2:$U$170))*100 -> 7.4326514 | AU8: =(V8-MIN($V$2:$V$170))/(MAX($V$2:$V$170)-MIN($V$2:$V$170))*100 -> 3.1237645 | AV8: =(W8-MIN($W$2:$W$170))/(MAX($W$2:$W$170)-MIN($W$2:$W$170))*100 -> 0.17859522 | AW8: =(X8-MIN($X$2:$X$170))/(MAX($X$2:$X$170)-MIN($X$2:$X$170))*100 -> 8.0511821 | AX8: =(Y8-MIN($Y$2:$Y$170))/(MAX($Y$2:$Y$170)-MIN($Y$2:$Y$170))*100 -> 3.3924196 | AY8: =(Z8-MIN($Z$2:$Z$170))/(MAX($Z$2:$Z$170)-MIN($Z$2:$Z$170))*100 -> 0.96660053 | AZ8: =(AA8-MIN($AA$2:$AA$170))/(MAX($AA$2:$AA$170)-MIN($AA$2:$AA$170))*100 -> 3.6472604 | BA8: =(AB8-MIN($AB$2:$AB$170))/(MAX($AB$2:$AB$170)-MIN($AB$2:$AB$170))*100 -> 0.93666355 | BB8: =(AC8-MIN($AC$2:$AC$170))/(MAX($AC$2:$AC$170)-MIN($AC$2:$AC$170))*100 -> 2.5600512 | BC8: 3.3 | BD8: 137970 | BE8: 0 | BF8: 0
A9: AREQUIPA | B9: AREQUIPA | C9: CAYMA | D9: 040103 | E9: 1055 | F9: 829.7999 | G9: 0.78654019 | H9: 119 | I9: 6220738.4 | J9: 52275.113 | K9: 116 | L9: 6188442 | M9: 53349 | N9: 294794.34 | O9: 28305.06 | P9: 1626179.5 | Q9: 0.87 | R9: 16819833 | S9: 363516.61 | T9: =IF((100-IFERROR(S9/R9*100,0))=100,50,(100-IFERROR(S9/R9*100,0))) -> 97.838762 | U9: 8595 | V9: 20014283 | W9: 3644454.2 | X9: 3778 | Y9: 11554579 | Z9: 3482681 | AA9: 543688 | AB9: 66746563 | AC9: 995162 | AD9: =(E9-MIN($E$2:$E$170))/(MAX($E$2:$E$170)-MIN($E$2:$E$170))*100 -> 7.2279204 | AE9: =(F9-MIN($F$2:$F$170))/(MAX($F$2:$F$170)-MIN($F$2:$F$170))*100 -> 7.3171081 | AF9: =(G9-MIN($G$2:$G$170))/(MAX($G$2:$G$170)-MIN($G$2:$G$170))*100 -> 38.216045 | AG9: =(H9-MIN($H$2:$H$170))/(MAX($H$2:$H$170)-MIN($H$2:$H$170))*100 -> 5.8162268 | AH9: =(I9-MIN($I$2:$I$170))/(MAX($I$2:$I$170)-MIN($I$2:$I$170))*100 -> 4.6574983 | AI9: =(J9-MIN($J$2:$J$170))/(MAX($J$2:$J$170)-MIN($J$2:$J$170))*100 -> 26.576798 | AJ9: =(K9-MIN($K$2:$K$170))/(MAX($K$2:$K$170)-MIN($K$2:$K$170))*100 -> 5.8232932 | AK9: =(L9-MIN($L$2:$L$170))/(MAX($L$2:$L$170)-MIN($L$2:$L$170))*100 -> 4.7785424 | AL9: =(M9-MIN($M$2:$M$170))/(MAX($M$2:$M$170)-MIN($M$2:$M$170))*100 -> 27.122703 | AM9: =(N9-MIN($N$2:$N$170))/(MAX($N$2:$N$170)-MIN($N$2:$N$170))*100 -> 3.1567086 | AN9: =(O9-MIN($O$2:$O$170))/(MAX($O$2:$O$170)-MIN($O$2:$O$170))*100 -> 10.485558 | AO9: =(P9-MIN($P$2:$P$170))/(MAX($P$2:$P$170)-MIN($P$2:$P$170))*100 -> 6.6079337 | AP9: =(Q9-MIN($Q$2:$Q$170))/(MAX($Q$2:$Q$170)-MIN($Q$2:$Q$170))*100 -> 87 | AQ9: =IF(AP9>=50,AP9,50) -> 87 | AR9: =(#REF!-MIN(#REF!))/(MAX(#REF!)-MIN(#REF!))*100 -> #REF! | AS9: =IF(AR9>=50,AR9,50) -> #REF! | AT9: =(U9-MIN($U$2:$U$170))/(MAX($U$2:$U$170)-MIN($U$2:$U$170))*100 -> 8.9129094 | AU9: =(V9-MIN($V$2:$V$170))/(MAX($V$2:$V$170)-MIN($V$2:$V$170))*100 -> 3.6247725 | AV9: =(W9-MIN($W$2:$W$170))/(MAX($W$2:$W$170)-MIN($W$2:$W$170))*100 -> 0.35584022 | AW9: =(X9-MIN($X$2:$X$170))/(MAX($X$2:$X$170)-MIN($X$2:$X$170))*100 -> 9.8862619 | AX9: =(Y9-MIN($Y$2:$Y$170))/(MAX($Y$2:$Y$170)-MIN($Y$2:$Y$170))*100 -> 3.5734593 | AY9: =(Z9-MIN($Z$2:$Z$170))/(MAX($Z$2:$Z$170)-MIN($Z$2:$Z$170))*100 -> 4.6217651 | AZ9: =(AA9-MIN($AA$2:$AA$170))/(MAX($AA$2:$AA$170)-MIN($AA$2:$AA$170))*100 -> 22.463506 | BA9: =(AB9-MIN($AB$2:$AB$170))/(MAX($AB$2:$AB$170)-MIN($AB$2:$AB$170))*100 -> 12.105167 | BB9: =(AC9-MIN($AC$2:$AC$170))/(MAX($AC$2:$AC$170)-MIN($AC$2:$AC$170))*100 -> 16.124535 | BC9: 3.6 | BD9: 165965 | BE9: 0 | BF9: 0
A10: AREQUIPA | B10: AREQUIPA | C10: CERRO COLORADO | D10: 040104 | E10: 2099 | F10: 1647.1315 | G10: 0.78472202 | H10: 266 | I10: 15947399 | J10: 59952.63 | K10: 260 | L10: 15752254 | M10: 60586 | N10: 624849.6 | O10: 88018.57 | P10: 3492921.9 | Q10: 0.93 | R10: 48907211 | S10: 419795.1 | T10: =IF((100-IFERROR(S10/R10*100,0))=100,50,(100-IFERROR(S10/R10*100,0))) -> 99.14165 | U10: 17090 | V10: 28273277 | W10: 9091918.5 | X10: 8642 | Y10: 16838791 | Z10: 4322266 | AA10: 432699 | AB10: 93252328 | AC10: 804433 | AD10: =(E10-MIN($E$2:$E$170))/(MAX($E$2:$E$170)-MIN($E$2:$E$170))*100 -> 14.414538 | AE10: =(F10-MIN($F$2:$F$170))/(MAX($F$2:$F$170)-MIN($F$2:$F$170))*100 -> 14.545788 | AF10: =(G10-MIN($G$2:$G$170))/(MAX($G$2:$G$170)-MIN($G$2:$G$170))*100 -> 38.055832 | AG10: =(H10-MIN($H$2:$H$170))/(MAX($H$2:$H$170)-MIN($H$2:$H$170))*100 -> 13.000978 | AH10: =(I10-MIN($I$2:$I$170))/(MAX($I$2:$I$170)-MIN($I$2:$I$170))*100 -> 11.939899 | AI10: =(J10-MIN($J$2:$J$170))/(MAX($J$2:$J$170)-MIN($J$2:$J$170))*100 -> 30.480067 | AJ10: =(K10-MIN($K$2:$K$170))/(MAX($K$2:$K$170)-MIN($K$2:$K$170))*100 -> 13.052209 | AK10: =(L10-MIN($L$2:$L$170))/(MAX($L$2:$L$170)-MIN($L$2:$L$170))*100 -> 12.163451 | AL10: =(M10-MIN($M$2:$M$170))/(MAX($M$2:$M$170)-MIN($M$2:$M$170))*100 -> 30.802003 | AM10: =(N10-MIN($N$2:$N$170))/(MAX($N$2:$N$170)-MIN($N$2:$N$170))*100 -> 6.6909972 | AN10: =(O10-MIN($O$2:$O$170))/(MAX($O$2:$O$170)-MIN($O$2:$O$170))*100 -> 32.606319 | AO10: =(P10-MIN($P$2:$P$170))/(MAX($P$2:$P$170)-MIN($P$2:$P$170))*100 -> 14.193388 | AP10: =(Q10-MIN($Q$2:$Q$170))/(MAX($Q$2:$Q$170)-MIN($Q$2:$Q$170))*100 -> 93 | AQ10: =IF(AP10>=50,AP10,50) -> 93 | AR10: =(#REF!-MIN(#REF!))/(MAX(#REF!)-MIN(#REF!))*100 -> #REF! | AS10: =IF(AR10>=50,AR10,50) -> #REF! | AT10: =(U10-MIN($U$2:$U$170))/(MAX($U$2:$U$170)-MIN($U$2:$U$170))*100 -> 17.793412 | AU10: =(V10-MIN($V$2:$V$170))/(MAX($V$2:$V$170)-MIN($V$2:$V$170))*100 -> 5.1292494 | AV10: =(W10-MIN($W$2:$W$170))/(MAX($W$2:$W$170)-MIN($W$2:$W$170))*100 -> 0.8877489 | AW10: =(X10-MIN($X$2:$X$170))/(MAX($X$2:$X$170)-MIN($X$2:$X$170))*100 -> 22.692328 | AX10: =(Y10-MIN($Y$2:$Y$170))/(MAX($Y$2:$Y$170)-MIN($Y$2:$Y$170))*100 -> 5.2163368 | AY10: =(Z10-MIN($Z$2:$Z$170))/(MAX($Z$2:$Z$170)-MIN($Z$2:$Z$170))*100 -> 5.7360082 | AZ10: =(AA10-MIN($AA$2:$AA$170))/(MAX($AA$2:$AA$170)-MIN($AA$2:$AA$170))*100 -> 17.877303 | BA10: =(AB10-MIN($AB$2:$AB$170))/(MAX($AB$2:$AB$170)-MIN($AB$2:$AB$170))*100 -> 16.912257 | BB10: =(AC10-MIN($AC$2:$AC$170))/(MAX($AC$2:$AC$170)-MIN($AC$2:$AC$170))*100 -> 13.033966 | BC10: 6.5 | BD10: 316064 | BE10: 0 | BF10: 0
